Workbook

Sheet 30 ABRIL (JUEVES)
A2: =TODAY()-1 -> 46133
I4: Turno | K4: Jaq | M4: Smit | O4: 300 | Q4: Karl M
I5: 1ro. | K5: =U43 -> #DIV/0! | M5: =U61 -> #DIV/0! | O5: =U92 -> #DIV/0! | Q5: =U103 -> #DIV/0!
A7: RESUMEN DE EFICIENCIAS | I7: 2do. | K7: =U132 -> #DIV/0! | M7: =U150 -> #DIV/0! | O7: =U181 -> #DIV/0! | Q7: =U192 -> #DIV/0!
I9: 3er | K9: =+U221 -> #DIV/0! | M9: =+U239 -> #DIV/0! | O9: =+U270 -> #DIV/0! | Q9: =U281 -> #DIV/0!
I11: 4to. | K11: =+U310 -> 0 | M11: =+U328 -> 0 | O11: =+U359 -> 0 | Q11: =U343 -> 0
H13: Promedio | K13: =(K11+K9+K7+K5)/3 -> #DIV/0! | M13: =(M11+M9+M7+M5)/3 -> #DIV/0! | O13: =(O11+O9+O7+O5)/3 -> #DIV/0! | Q13: =(Q11+Q9+Q7+Q5)/3 -> #DIV/0!
A18: PRIMER TURNO PRIMER TURNO PRIMER TURNO
A19: 1 TURNO | B19: HORARIO: | K19: SUPERVISOR: | R19: DIA: | W19: FECHA:
A21: COMENTARIO DE PERSONAL
A25: F=FALTA, P=PERMISO, R=RETARDO, C=CASTIGO, I=INCAPACIDAD, V=VACACIONES, FL=FESTIVO LABORADO, FD=FESTIVO DESCANSADO, CL=CAMBIO DE LUGAR, B=BAJA, CT=CAMBIO DE TURNO
A27: Observaciones:
G30: Mínimo | H30: Máximo
A31: JACQUARD | B31: TEMPERATURA | G31: ='29 ABRIL (MIERCOLES)'!G31 -> 20 | H31: ='29 ABRIL (MIERCOLES)'!H31 -> 29 | Q31: =AVERAGE(K31,M31,O31) -> #DIV/0! | V31: =AVERAGE(S36:S41) -> 8.5
A32: SULZER | B32: HUMEDAD | G32: ='29 ABRIL (MIERCOLES)'!G32 -> 60 | H32: ='29 ABRIL (MIERCOLES)'!H32 -> 75 | Q32: =AVERAGE(K32,M32,O32) -> #DIV/0! | S32: MAQUINAS TRABAJANDO | V32: =COUNT(S36:S41) -> 6
K34: Marcador | M34: Marcador | O34: Marcas | S34: Horas | U34: Eficiencia | W34: Temp.
A35: Observaciones | B35: R | C35: P | D35: L | E35: tiempo | H35: vel | I35: telar | K35: Inicial | M35: Final | S35: 8.5
I36: 207 | K36: ='29 ABRIL (MIERCOLES)'!M36 -> 553941 | M36: =K36+O36 -> 553941 | S36: =+S35 -> 8.5 | U36: =O36/(H36*60*S36)*100000 -> #DIV/0!
I37: 208 | K37: ='29 ABRIL (MIERCOLES)'!M37 -> 617577 | M37: =K37+O37 -> 617577 | S37: =+S36 -> 8.5 | U37: =O37/(H37*60*S37)*100000 -> #DIV/0!
I38: 209 | K38: ='29 ABRIL (MIERCOLES)'!M38 -> 595396 | M38: =K38+O38 -> 595396 | S38: =+S37 -> 8.5 | U38: =O38/(H38*60*S38)*100000 -> #DIV/0!
I39: 210 | K39: ='29 ABRIL (MIERCOLES)'!M39 -> 682073.4 | M39: =K39+O39 -> 682073.4 | S39: =+S38 -> 8.5 | U39: =O39/(H39*60*S39)*100000 -> #DIV/0!
I40: 211 | K40: ='29 ABRIL (MIERCOLES)'!M40 -> 739209.5 | M40: =K40+O40 -> 739209.5 | S40: =+S39 -> 8.5 | U40: =O40/(H40*60*S40)*100000 -> #DIV/0!
I41: 212 | K41: ='29 ABRIL (MIERCOLES)'!M41 -> 0 | M41: =K41+O41 -> 0 | S41: =+S40 -> 8.5 | U41: =O41/(H41*60*S41)*100000 -> #DIV/0!
U43: =AVERAGE(U36:U41) -> #DIV/0! | W43: =AVERAGE(W36:W41) -> #DIV/0!
G45: Mínimo | H45: Máximo
A46: JACQUARD | B46: TEMPERATURA | G46: =$G$31 -> 20 | H46: =$H$31 -> 29 | Q46: =AVERAGE(K46,M46,O46) -> #DIV/0! | V46: =AVERAGE(S51:S59) -> 8.5
A47: SMIT | B47: HUMEDAD | G47: =$G$32 -> 60 | H47: =$H$32 -> 75 | Q47: =AVERAGE(K47,M47,O47) -> #DIV/0! | S47: MAQUINAS TRABAJANDO | V47: =COUNT(S51:S59) -> 9
K49: Marcador | M49: Marcador | O49: Marcas | S49: Horas | U49: Eficiencia | W49: Temp.
A50: Observaciones | B50: R | C50: P | D50: L | E50: tiempo | H50: vel | I50: telar | K50: Inicial | M50: Final | S50: 8.5
I51: 201 | K51: ='29 ABRIL (MIERCOLES)'!M51 -> 647180.6 | M51: =K51+O51 -> 647180.6 | S51: =+S50 -> 8.5 | U51: =O51/(H51*60*S51)*100000 -> #DIV/0!
I52: 202 | K52: ='29 ABRIL (MIERCOLES)'!M52 -> 753490.7 | M52: =K52+O52 -> 753490.7 | S52: =+S51 -> 8.5 | U52: =O52/(H52*60*S52)*100000 -> #DIV/0!
I53: 203 | K53: ='29 ABRIL (MIERCOLES)'!M53 -> 654637.8 | M53: =K53+O53 -> 654637.8 | S53: =+S52 -> 8.5 | U53: =O53/(H53*60*S53)*100000 -> #DIV/0!
I54: 204 | K54: ='29 ABRIL (MIERCOLES)'!M54 -> 662768.7 | M54: =K54+O54 -> 662768.7 | S54: =+S53 -> 8.5 | U54: =O54/(H54*60*S54)*100000 -> #DIV/0!
I55: 205 | K55: ='29 ABRIL (MIERCOLES)'!M55 -> 647848.7 | M55: =K55+O55 -> 647848.7 | S55: =+S54 -> 8.5 | U55: =O55/(H55*60*S55)*100000 -> #DIV/0!
I56: 206 | K56: ='29 ABRIL (MIERCOLES)'!M56 -> 677636.3 | M56: =K56+O56 -> 677636.3 | S56: =+S55 -> 8.5 | U56: =O56/(H56*60*S56)*100000 -> #DIV/0!
I57: 213 | K57: ='29 ABRIL (MIERCOLES)'!M57 -> 633388.9 | M57: =K57+O57 -> 633388.9 | S57: =+S56 -> 8.5 | U57: =O57/(H57*60*S57)*100000 -> #DIV/0!
I58: 214 | K58: ='29 ABRIL (MIERCOLES)'!M58 -> 657550.9 | M58: =K58+O58 -> 657550.9 | S58: =+S57 -> 8.5 | U58: =O58/(H58*60*S58)*100000 -> #DIV/0!
I59: 215 | K59: ='29 ABRIL (MIERCOLES)'!M59 -> 694890.2 | M59: =K59+O59 -> 694890.2 | S59: =+S58 -> 8.5 | U59: =O59/(H59*60*S59)*100000 -> #DIV/0!
U61: =AVERAGE(U51:U59) -> #DIV/0! | W61: =AVERAGE(W51:W58) -> #DIV/0!
G63: Mínimo | H63: Máximo
...

Sheet 29 ABRIL (MIERCOLES)
A2: =TODAY()-1 -> 46133
I4: Turno | K4: Jaq | M4: Smit | O4: 300 | Q4: Karl M
I5: 1ro. | K5: =U43 -> #DIV/0! | M5: =U61 -> #DIV/0! | O5: =U92 -> #DIV/0! | Q5: =U103 -> #DIV/0!
A7: RESUMEN DE EFICIENCIAS | I7: 2do. | K7: =U132 -> #DIV/0! | M7: =U150 -> #DIV/0! | O7: =U181 -> #DIV/0! | Q7: =U192 -> #DIV/0!
I9: 3er | K9: =+U221 -> #DIV/0! | M9: =+U239 -> #DIV/0! | O9: =+U270 -> #DIV/0! | Q9: =U281 -> #DIV/0!
I11: 4to. | K11: =+U310 -> 0 | M11: =+U328 -> 0 | O11: =+U359 -> 0 | Q11: =U343 -> 0
H13: Promedio | K13: =(K11+K9+K7+K5)/3 -> #DIV/0! | M13: =(M11+M9+M7+M5)/3 -> #DIV/0! | O13: =(O11+O9+O7+O5)/3 -> #DIV/0! | Q13: =(Q11+Q9+Q7+Q5)/3 -> #DIV/0!
A18: PRIMER TURNO PRIMER TURNO PRIMER TURNO
A19: 1 TURNO | B19: HORARIO: | K19: SUPERVISOR: | R19: DIA: | W19: FECHA:
A21: COMENTARIO DE PERSONAL
A25: F=FALTA, P=PERMISO, R=RETARDO, C=CASTIGO, I=INCAPACIDAD, V=VACACIONES, FL=FESTIVO LABORADO, FD=FESTIVO DESCANSADO, CL=CAMBIO DE LUGAR, B=BAJA, CT=CAMBIO DE TURNO
A27: Observaciones:
G30: Mínimo | H30: Máximo
A31: JACQUARD | B31: TEMPERATURA | G31: ='28 ABRIL (MARTES)'!G31 -> 20 | H31: ='28 ABRIL (MARTES)'!H31 -> 29 | Q31: =AVERAGE(K31,M31,O31) -> #DIV/0! | V31: =AVERAGE(S36:S41) -> 8.5
A32: SULZER | B32: HUMEDAD | G32: ='28 ABRIL (MARTES)'!G32 -> 60 | H32: ='28 ABRIL (MARTES)'!H32 -> 75 | Q32: =AVERAGE(K32,M32,O32) -> #DIV/0! | S32: MAQUINAS TRABAJANDO | V32: =COUNT(S36:S41) -> 6
K34: Marcador | M34: Marcador | O34: Marcas | S34: Horas | U34: Eficiencia | W34: Temp.
A35: Observaciones | B35: R | C35: P | D35: L | E35: tiempo | H35: vel | I35: telar | K35: Inicial | M35: Final | S35: 8.5
I36: 207 | K36: ='28 ABRIL (MARTES)'!M36 -> 553941 | M36: =K36+O36 -> 553941 | S36: =+S35 -> 8.5 | U36: =O36/(H36*60*S36)*100000 -> #DIV/0!
I37: 208 | K37: ='28 ABRIL (MARTES)'!M37 -> 617577 | M37: =K37+O37 -> 617577 | S37: =+S36 -> 8.5 | U37: =O37/(H37*60*S37)*100000 -> #DIV/0!
I38: 209 | K38: ='28 ABRIL (MARTES)'!M38 -> 595396 | M38: =K38+O38 -> 595396 | S38: =+S37 -> 8.5 | U38: =O38/(H38*60*S38)*100000 -> #DIV/0!
I39: 210 | K39: ='28 ABRIL (MARTES)'!M39 -> 682073.4 | M39: =K39+O39 -> 682073.4 | S39: =+S38 -> 8.5 | U39: =O39/(H39*60*S39)*100000 -> #DIV/0!
I40: 211 | K40: ='28 ABRIL (MARTES)'!M40 -> 739209.5 | M40: =K40+O40 -> 739209.5 | S40: =+S39 -> 8.5 | U40: =O40/(H40*60*S40)*100000 -> #DIV/0!
I41: 212 | K41: ='28 ABRIL (MARTES)'!M41 -> 0 | M41: =K41+O41 -> 0 | S41: =+S40 -> 8.5 | U41: =O41/(H41*60*S41)*100000 -> #DIV/0!
U43: =AVERAGE(U36:U41) -> #DIV/0! | W43: =AVERAGE(W36:W41) -> #DIV/0!
G45: Mínimo | H45: Máximo
A46: JACQUARD | B46: TEMPERATURA | G46: =$G$31 -> 20 | H46: =$H$31 -> 29 | Q46: =AVERAGE(K46,M46,O46) -> #DIV/0! | V46: =AVERAGE(S51:S59) -> 8.5
A47: SMIT | B47: HUMEDAD | G47: =$G$32 -> 60 | H47: =$H$32 -> 75 | Q47: =AVERAGE(K47,M47,O47) -> #DIV/0! | S47: MAQUINAS TRABAJANDO | V47: =COUNT(S51:S59) -> 9
K49: Marcador | M49: Marcador | O49: Marcas | S49: Horas | U49: Eficiencia | W49: Temp.
A50: Observaciones | B50: R | C50: P | D50: L | E50: tiempo | H50: vel | I50: telar | K50: Inicial | M50: Final | S50: 8.5
I51: 201 | K51: ='28 ABRIL (MARTES)'!M51 -> 647180.6 | M51: =K51+O51 -> 647180.6 | S51: =+S50 -> 8.5 | U51: =O51/(H51*60*S51)*100000 -> #DIV/0!
I52: 202 | K52: ='28 ABRIL (MARTES)'!M52 -> 753490.7 | M52: =K52+O52 -> 753490.7 | S52: =+S51 -> 8.5 | U52: =O52/(H52*60*S52)*100000 -> #DIV/0!
I53: 203 | K53: ='28 ABRIL (MARTES)'!M53 -> 654637.8 | M53: =K53+O53 -> 654637.8 | S53: =+S52 -> 8.5 | U53: =O53/(H53*60*S53)*100000 -> #DIV/0!
I54: 204 | K54: ='28 ABRIL (MARTES)'!M54 -> 662768.7 | M54: =K54+O54 -> 662768.7 | S54: =+S53 -> 8.5 | U54: =O54/(H54*60*S54)*100000 -> #DIV/0!
I55: 205 | K55: ='28 ABRIL (MARTES)'!M55 -> 647848.7 | M55: =K55+O55 -> 647848.7 | S55: =+S54 -> 8.5 | U55: =O55/(H55*60*S55)*100000 -> #DIV/0!
I56: 206 | K56: ='28 ABRIL (MARTES)'!M56 -> 677636.3 | M56: =K56+O56 -> 677636.3 | S56: =+S55 -> 8.5 | U56: =O56/(H56*60*S56)*100000 -> #DIV/0!
I57: 213 | K57: ='28 ABRIL (MARTES)'!M57 -> 633388.9 | M57: =K57+O57 -> 633388.9 | S57: =+S56 -> 8.5 | U57: =O57/(H57*60*S57)*100000 -> #DIV/0!
I58: 214 | K58: ='28 ABRIL (MARTES)'!M58 -> 657550.9 | M58: =K58+O58 -> 657550.9 | S58: =+S57 -> 8.5 | U58: =O58/(H58*60*S58)*100000 -> #DIV/0!
I59: 215 | K59: ='28 ABRIL (MARTES)'!M59 -> 694890.2 | M59: =K59+O59 -> 694890.2 | S59: =+S58 -> 8.5 | U59: =O59/(H59*60*S59)*100000 -> #DIV/0!
U61: =AVERAGE(U51:U59) -> #DIV/0! | W61: =AVERAGE(W51:W58) -> #DIV/0!
G63: Mínimo | H63: Máximo
...

Sheet 28 ABRIL (MARTES)
A2: =TODAY()-1 -> 46133
I4: Turno | K4: Jaq | M4: Smit | O4: 300 | Q4: Karl M
I5: 1ro. | K5: =U43 -> #DIV/0! | M5: =U61 -> #DIV/0! | O5: =U92 -> #DIV/0! | Q5: =U103 -> #DIV/0!
A7: RESUMEN DE EFICIENCIAS | I7: 2do. | K7: =U132 -> #DIV/0! | M7: =U150 -> #DIV/0! | O7: =U181 -> #DIV/0! | Q7: =U192 -> #DIV/0!
I9: 3er | K9: =+U221 -> #DIV/0! | M9: =+U239 -> #DIV/0! | O9: =+U270 -> #DIV/0! | Q9: =U281 -> #DIV/0!
I11: 4to. | K11: =+U310 -> 0 | M11: =+U328 -> 0 | O11: =+U359 -> 0 | Q11: =U343 -> 0
H13: Promedio | K13: =(K11+K9+K7+K5)/3 -> #DIV/0! | M13: =(M11+M9+M7+M5)/3 -> #DIV/0! | O13: =(O11+O9+O7+O5)/3 -> #DIV/0! | Q13: =(Q11+Q9+Q7+Q5)/3 -> #DIV/0!
A18: PRIMER TURNO PRIMER TURNO PRIMER TURNO
A19: 1 TURNO | B19: HORARIO: | K19: SUPERVISOR: | R19: DIA: | W19: FECHA:
A21: COMENTARIO DE PERSONAL
A25: F=FALTA, P=PERMISO, R=RETARDO, C=CASTIGO, I=INCAPACIDAD, V=VACACIONES, FL=FESTIVO LABORADO, FD=FESTIVO DESCANSADO, CL=CAMBIO DE LUGAR, B=BAJA, CT=CAMBIO DE TURNO
A27: Observaciones:
G30: Mínimo | H30: Máximo
A31: JACQUARD | B31: TEMPERATURA | G31: ='27 ABRIL (LUNES)'!G31 -> 20 | H31: ='27 ABRIL (LUNES)'!H31 -> 29 | Q31: =AVERAGE(K31,M31,O31) -> #DIV/0! | V31: =AVERAGE(S36:S41) -> 8.5
A32: SULZER | B32: HUMEDAD | G32: ='27 ABRIL (LUNES)'!G32 -> 60 | H32: ='27 ABRIL (LUNES)'!H32 -> 75 | Q32: =AVERAGE(K32,M32,O32) -> #DIV/0! | S32: MAQUINAS TRABAJANDO | V32: =COUNT(S36:S41) -> 6
K34: Marcador | M34: Marcador | O34: Marcas | S34: Horas | U34: Eficiencia | W34: Temp.
A35: Observaciones | B35: R | C35: P | D35: L | E35: tiempo | H35: vel | I35: telar | K35: Inicial | M35: Final | S35: 8.5
I36: 207 | K36: ='27 ABRIL (LUNES)'!M36 -> 553941 | M36: =K36+O36 -> 553941 | S36: =+S35 -> 8.5 | U36: =O36/(H36*60*S36)*100000 -> #DIV/0!
I37: 208 | K37: ='27 ABRIL (LUNES)'!M37 -> 617577 | M37: =K37+O37 -> 617577 | S37: =+S36 -> 8.5 | U37: =O37/(H37*60*S37)*100000 -> #DIV/0!
I38: 209 | K38: ='27 ABRIL (LUNES)'!M38 -> 595396 | M38: =K38+O38 -> 595396 | S38: =+S37 -> 8.5 | U38: =O38/(H38*60*S38)*100000 -> #DIV/0!
I39: 210 | K39: ='27 ABRIL (LUNES)'!M39 -> 682073.4 | M39: =K39+O39 -> 682073.4 | S39: =+S38 -> 8.5 | U39: =O39/(H39*60*S39)*100000 -> #DIV/0!
I40: 211 | K40: ='27 ABRIL (LUNES)'!M40 -> 739209.5 | M40: =K40+O40 -> 739209.5 | S40: =+S39 -> 8.5 | U40: =O40/(H40*60*S40)*100000 -> #DIV/0!
I41: 212 | K41: ='27 ABRIL (LUNES)'!M41 -> 0 | M41: =K41+O41 -> 0 | S41: =+S40 -> 8.5 | U41: =O41/(H41*60*S41)*100000 -> #DIV/0!
U43: =AVERAGE(U36:U41) -> #DIV/0! | W43: =AVERAGE(W36:W41) -> #DIV/0!
G45: Mínimo | H45: Máximo
A46: JACQUARD | B46: TEMPERATURA | G46: =$G$31 -> 20 | H46: =$H$31 -> 29 | Q46: =AVERAGE(K46,M46,O46) -> #DIV/0! | V46: =AVERAGE(S51:S59) -> 8.5
A47: SMIT | B47: HUMEDAD | G47: =$G$32 -> 60 | H47: =$H$32 -> 75 | Q47: =AVERAGE(K47,M47,O47) -> #DIV/0! | S47: MAQUINAS TRABAJANDO | V47: =COUNT(S51:S59) -> 9
K49: Marcador | M49: Marcador | O49: Marcas | S49: Horas | U49: Eficiencia | W49: Temp.
A50: Observaciones | B50: R | C50: P | D50: L | E50: tiempo | H50: vel | I50: telar | K50: Inicial | M50: Final | S50: 8.5
I51: 201 | K51: ='27 ABRIL (LUNES)'!M51 -> 647180.6 | M51: =K51+O51 -> 647180.6 | S51: =+S50 -> 8.5 | U51: =O51/(H51*60*S51)*100000 -> #DIV/0!
I52: 202 | K52: ='27 ABRIL (LUNES)'!M52 -> 753490.7 | M52: =K52+O52 -> 753490.7 | S52: =+S51 -> 8.5 | U52: =O52/(H52*60*S52)*100000 -> #DIV/0!
I53: 203 | K53: ='27 ABRIL (LUNES)'!M53 -> 654637.8 | M53: =K53+O53 -> 654637.8 | S53: =+S52 -> 8.5 | U53: =O53/(H53*60*S53)*100000 -> #DIV/0!
I54: 204 | K54: ='27 ABRIL (LUNES)'!M54 -> 662768.7 | M54: =K54+O54 -> 662768.7 | S54: =+S53 -> 8.5 | U54: =O54/(H54*60*S54)*100000 -> #DIV/0!
I55: 205 | K55: ='27 ABRIL (LUNES)'!M55 -> 647848.7 | M55: =K55+O55 -> 647848.7 | S55: =+S54 -> 8.5 | U55: =O55/(H55*60*S55)*100000 -> #DIV/0!
I56: 206 | K56: ='27 ABRIL (LUNES)'!M56 -> 677636.3 | M56: =K56+O56 -> 677636.3 | S56: =+S55 -> 8.5 | U56: =O56/(H56*60*S56)*100000 -> #DIV/0!
I57: 213 | K57: ='27 ABRIL (LUNES)'!M57 -> 633388.9 | M57: =K57+O57 -> 633388.9 | S57: =+S56 -> 8.5 | U57: =O57/(H57*60*S57)*100000 -> #DIV/0!
I58: 214 | K58: ='27 ABRIL (LUNES)'!M58 -> 657550.9 | M58: =K58+O58 -> 657550.9 | S58: =+S57 -> 8.5 | U58: =O58/(H58*60*S58)*100000 -> #DIV/0!
I59: 215 | K59: ='27 ABRIL (LUNES)'!M59 -> 694890.2 | M59: =K59+O59 -> 694890.2 | S59: =+S58 -> 8.5 | U59: =O59/(H59*60*S59)*100000 -> #DIV/0!
U61: =AVERAGE(U51:U59) -> #DIV/0! | W61: =AVERAGE(W51:W58) -> #DIV/0!
G63: Mínimo | H63: Máximo
...

Sheet 27 ABRIL (LUNES)
A2: =TODAY()-1 -> 46133
I4: Turno | K4: Jaq | M4: Smit | O4: 300 | Q4: Karl M
I5: 1ro. | K5: =U43 -> #DIV/0! | M5: =U61 -> #DIV/0! | O5: =U92 -> #DIV/0! | Q5: =U103 -> #DIV/0!
A7: RESUMEN DE EFICIENCIAS | I7: 2do. | K7: =U132 -> #DIV/0! | M7: =U150 -> #DIV/0! | O7: =U181 -> #DIV/0! | Q7: =U192 -> #DIV/0!
I9: 3er | K9: =+U221 -> #DIV/0! | M9: =+U239 -> #DIV/0! | O9: =+U270 -> #DIV/0! | Q9: =U281 -> #DIV/0!
I11: 4to. | K11: =+U310 -> 0 | M11: =+U328 -> 0 | O11: =+U359 -> 0 | Q11: =U343 -> 0
H13: Promedio | K13: =(K11+K9+K7+K5)/3 -> #DIV/0! | M13: =(M11+M9+M7+M5)/3 -> #DIV/0! | O13: =(O11+O9+O7+O5)/3 -> #DIV/0! | Q13: =(Q11+Q9+Q7+Q5)/3 -> #DIV/0!
A18: PRIMER TURNO PRIMER TURNO PRIMER TURNO
A19: 1 TURNO | B19: HORARIO: | K19: SUPERVISOR: | R19: DIA: | W19: FECHA:
A21: COMENTARIO DE PERSONAL
A25: F=FALTA, P=PERMISO, R=RETARDO, C=CASTIGO, I=INCAPACIDAD, V=VACACIONES, FL=FESTIVO LABORADO, FD=FESTIVO DESCANSADO, CL=CAMBIO DE LUGAR, B=BAJA, CT=CAMBIO DE TURNO
A27: Observaciones:
G30: Mínimo | H30: Máximo
A31: JACQUARD | B31: TEMPERATURA | G31: ='26 ABRIL (DOMINGO)'!G31 -> 20 | H31: ='26 ABRIL (DOMINGO)'!H31 -> 29 | Q31: =AVERAGE(K31,M31,O31) -> #DIV/0! | V31: =AVERAGE(S36:S41) -> 8.5
A32: SULZER | B32: HUMEDAD | G32: ='26 ABRIL (DOMINGO)'!G32 -> 60 | H32: ='26 ABRIL (DOMINGO)'!H32 -> 75 | Q32: =AVERAGE(K32,M32,O32) -> #DIV/0! | S32: MAQUINAS TRABAJANDO | V32: =COUNT(S36:S41) -> 6
K34: Marcador | M34: Marcador | O34: Marcas | S34: Horas | U34: Eficiencia | W34: Temp.
A35: Observaciones | B35: R | C35: P | D35: L | E35: tiempo | H35: vel | I35: telar | K35: Inicial | M35: Final | S35: 8.5
I36: 207 | K36: ='26 ABRIL (DOMINGO)'!M36 -> 553941 | M36: =K36+O36 -> 553941 | S36: =+S35 -> 8.5 | U36: =O36/(H36*60*S36)*100000 -> #DIV/0!
I37: 208 | K37: ='26 ABRIL (DOMINGO)'!M37 -> 617577 | M37: =K37+O37 -> 617577 | S37: =+S36 -> 8.5 | U37: =O37/(H37*60*S37)*100000 -> #DIV/0!
I38: 209 | K38: ='26 ABRIL (DOMINGO)'!M38 -> 595396 | M38: =K38+O38 -> 595396 | S38: =+S37 -> 8.5 | U38: =O38/(H38*60*S38)*100000 -> #DIV/0!
I39: 210 | K39: ='26 ABRIL (DOMINGO)'!M39 -> 682073.4 | M39: =K39+O39 -> 682073.4 | S39: =+S38 -> 8.5 | U39: =O39/(H39*60*S39)*100000 -> #DIV/0!
I40: 211 | K40: ='26 ABRIL (DOMINGO)'!M40 -> 739209.5 | M40: =K40+O40 -> 739209.5 | S40: =+S39 -> 8.5 | U40: =O40/(H40*60*S40)*100000 -> #DIV/0!
I41: 212 | K41: ='26 ABRIL (DOMINGO)'!M41 -> 0 | M41: =K41+O41 -> 0 | S41: =+S40 -> 8.5 | U41: =O41/(H41*60*S41)*100000 -> #DIV/0!
U43: =AVERAGE(U36:U41) -> #DIV/0! | W43: =AVERAGE(W36:W41) -> #DIV/0!
G45: Mínimo | H45: Máximo
A46: JACQUARD | B46: TEMPERATURA | G46: =$G$31 -> 20 | H46: =$H$31 -> 29 | Q46: =AVERAGE(K46,M46,O46) -> #DIV/0! | V46: =AVERAGE(S51:S59) -> 8.5
A47: SMIT | B47: HUMEDAD | G47: =$G$32 -> 60 | H47: =$H$32 -> 75 | Q47: =AVERAGE(K47,M47,O47) -> #DIV/0! | S47: MAQUINAS TRABAJANDO | V47: =COUNT(S51:S59) -> 9
K49: Marcador | M49: Marcador | O49: Marcas | S49: Horas | U49: Eficiencia | W49: Temp.
A50: Observaciones | B50: R | C50: P | D50: L | E50: tiempo | H50: vel | I50: telar | K50: Inicial | M50: Final | S50: 8.5
I51: 201 | K51: ='26 ABRIL (DOMINGO)'!M51 -> 647180.6 | M51: =K51+O51 -> 647180.6 | S51: =+S50 -> 8.5 | U51: =O51/(H51*60*S51)*100000 -> #DIV/0!
I52: 202 | K52: ='26 ABRIL (DOMINGO)'!M52 -> 753490.7 | M52: =K52+O52 -> 753490.7 | S52: =+S51 -> 8.5 | U52: =O52/(H52*60*S52)*100000 -> #DIV/0!
I53: 203 | K53: ='26 ABRIL (DOMINGO)'!M53 -> 654637.8 | M53: =K53+O53 -> 654637.8 | S53: =+S52 -> 8.5 | U53: =O53/(H53*60*S53)*100000 -> #DIV/0!
I54: 204 | K54: ='26 ABRIL (DOMINGO)'!M54 -> 662768.7 | M54: =K54+O54 -> 662768.7 | S54: =+S53 -> 8.5 | U54: =O54/(H54*60*S54)*100000 -> #DIV/0!
I55: 205 | K55: ='26 ABRIL (DOMINGO)'!M55 -> 647848.7 | M55: =K55+O55 -> 647848.7 | S55: =+S54 -> 8.5 | U55: =O55/(H55*60*S55)*100000 -> #DIV/0!
I56: 206 | K56: ='26 ABRIL (DOMINGO)'!M56 -> 677636.3 | M56: =K56+O56 -> 677636.3 | S56: =+S55 -> 8.5 | U56: =O56/(H56*60*S56)*100000 -> #DIV/0!
I57: 213 | K57: ='26 ABRIL (DOMINGO)'!M57 -> 633388.9 | M57: =K57+O57 -> 633388.9 | S57: =+S56 -> 8.5 | U57: =O57/(H57*60*S57)*100000 -> #DIV/0!
I58: 214 | K58: ='26 ABRIL (DOMINGO)'!M58 -> 657550.9 | M58: =K58+O58 -> 657550.9 | S58: =+S57 -> 8.5 | U58: =O58/(H58*60*S58)*100000 -> #DIV/0!
I59: 215 | K59: ='26 ABRIL (DOMINGO)'!M59 -> 694890.2 | M59: =K59+O59 -> 694890.2 | S59: =+S58 -> 8.5 | U59: =O59/(H59*60*S59)*100000 -> #DIV/0!
U61: =AVERAGE(U51:U59) -> #DIV/0! | W61: =AVERAGE(W51:W58) -> #DIV/0!
G63: Mínimo | H63: Máximo
...

Sheet 26 ABRIL (DOMINGO)
A2: =TODAY()-1 -> 46133
I4: Turno | K4: Jaq | M4: Smit | O4: 300 | Q4: Karl M
I5: 1ro. | K5: =U43 -> #DIV/0! | M5: =U61 -> #DIV/0! | O5: =U92 -> #DIV/0! | Q5: =U103 -> #DIV/0!
A7: RESUMEN DE EFICIENCIAS | I7: 2do. | K7: =U132 -> #DIV/0! | M7: =U150 -> #DIV/0! | O7: =U181 -> #DIV/0! | Q7: =U192 -> #DIV/0!
I9: 3er | K9: =+U221 -> #DIV/0! | M9: =+U239 -> #DIV/0! | O9: =+U270 -> #DIV/0! | Q9: =U281 -> #DIV/0!
I11: 4to. | K11: =+U310 -> 0 | M11: =+U328 -> 0 | O11: =+U359 -> 0 | Q11: =U343 -> 0
H13: Promedio | K13: =(K11+K9+K7+K5)/3 -> #DIV/0! | M13: =(M11+M9+M7+M5)/3 -> #DIV/0! | O13: =(O11+O9+O7+O5)/3 -> #DIV/0! | Q13: =(Q11+Q9+Q7+Q5)/3 -> #DIV/0!
A18: PRIMER TURNO PRIMER TURNO PRIMER TURNO
A19: 1 TURNO | B19: HORARIO: | K19: SUPERVISOR: | R19: DIA: | W19: FECHA:
A21: COMENTARIO DE PERSONAL
A25: F=FALTA, P=PERMISO, R=RETARDO, C=CASTIGO, I=INCAPACIDAD, V=VACACIONES, FL=FESTIVO LABORADO, FD=FESTIVO DESCANSADO, CL=CAMBIO DE LUGAR, B=BAJA, CT=CAMBIO DE TURNO
A27: Observaciones:
G30: Mínimo | H30: Máximo
A31: JACQUARD | B31: TEMPERATURA | G31: ='25 ABRIL (SABADO)'!G31 -> 20 | H31: ='25 ABRIL (SABADO)'!H31 -> 29 | Q31: =AVERAGE(K31,M31,O31) -> #DIV/0! | V31: =AVERAGE(S36:S41) -> 8.5
A32: SULZER | B32: HUMEDAD | G32: ='25 ABRIL (SABADO)'!G32 -> 60 | H32: ='25 ABRIL (SABADO)'!H32 -> 75 | Q32: =AVERAGE(K32,M32,O32) -> #DIV/0! | S32: MAQUINAS TRABAJANDO | V32: =COUNT(S36:S41) -> 6
K34: Marcador | M34: Marcador | O34: Marcas | S34: Horas | U34: Eficiencia | W34: Temp.
A35: Observaciones | B35: R | C35: P | D35: L | E35: tiempo | H35: vel | I35: telar | K35: Inicial | M35: Final | S35: 8.5
I36: 207 | K36: ='25 ABRIL (SABADO)'!M36 -> 553941 | M36: =K36+O36 -> 553941 | S36: =+S35 -> 8.5 | U36: =O36/(H36*60*S36)*100000 -> #DIV/0!
I37: 208 | K37: ='25 ABRIL (SABADO)'!M37 -> 617577 | M37: =K37+O37 -> 617577 | S37: =+S36 -> 8.5 | U37: =O37/(H37*60*S37)*100000 -> #DIV/0!
I38: 209 | K38: ='25 ABRIL (SABADO)'!M38 -> 595396 | M38: =K38+O38 -> 595396 | S38: =+S37 -> 8.5 | U38: =O38/(H38*60*S38)*100000 -> #DIV/0!
I39: 210 | K39: ='25 ABRIL (SABADO)'!M39 -> 682073.4 | M39: =K39+O39 -> 682073.4 | S39: =+S38 -> 8.5 | U39: =O39/(H39*60*S39)*100000 -> #DIV/0!
I40: 211 | K40: ='25 ABRIL (SABADO)'!M40 -> 739209.5 | M40: =K40+O40 -> 739209.5 | S40: =+S39 -> 8.5 | U40: =O40/(H40*60*S40)*100000 -> #DIV/0!
I41: 212 | K41: ='25 ABRIL (SABADO)'!M41 -> 0 | M41: =K41+O41 -> 0 | S41: =+S40 -> 8.5 | U41: =O41/(H41*60*S41)*100000 -> #DIV/0!
U43: =AVERAGE(U36:U41) -> #DIV/0! | W43: =AVERAGE(W36:W41) -> #DIV/0!
G45: Mínimo | H45: Máximo
A46: JACQUARD | B46: TEMPERATURA | G46: =$G$31 -> 20 | H46: =$H$31 -> 29 | Q46: =AVERAGE(K46,M46,O46) -> #DIV/0! | V46: =AVERAGE(S51:S59) -> 8.5
A47: SMIT | B47: HUMEDAD | G47: =$G$32 -> 60 | H47: =$H$32 -> 75 | Q47: =AVERAGE(K47,M47,O47) -> #DIV/0! | S47: MAQUINAS TRABAJANDO | V47: =COUNT(S51:S59) -> 9
K49: Marcador | M49: Marcador | O49: Marcas | S49: Horas | U49: Eficiencia | W49: Temp.
A50: Observaciones | B50: R | C50: P | D50: L | E50: tiempo | H50: vel | I50: telar | K50: Inicial | M50: Final | S50: 8.5
I51: 201 | K51: ='25 ABRIL (SABADO)'!M51 -> 647180.6 | M51: =K51+O51 -> 647180.6 | S51: =+S50 -> 8.5 | U51: =O51/(H51*60*S51)*100000 -> #DIV/0!
I52: 202 | K52: ='25 ABRIL (SABADO)'!M52 -> 753490.7 | M52: =K52+O52 -> 753490.7 | S52: =+S51 -> 8.5 | U52: =O52/(H52*60*S52)*100000 -> #DIV/0!
I53: 203 | K53: ='25 ABRIL (SABADO)'!M53 -> 654637.8 | M53: =K53+O53 -> 654637.8 | S53: =+S52 -> 8.5 | U53: =O53/(H53*60*S53)*100000 -> #DIV/0!
I54: 204 | K54: ='25 ABRIL (SABADO)'!M54 -> 662768.7 | M54: =K54+O54 -> 662768.7 | S54: =+S53 -> 8.5 | U54: =O54/(H54*60*S54)*100000 -> #DIV/0!
I55: 205 | K55: ='25 ABRIL (SABADO)'!M55 -> 647848.7 | M55: =K55+O55 -> 647848.7 | S55: =+S54 -> 8.5 | U55: =O55/(H55*60*S55)*100000 -> #DIV/0!
I56: 206 | K56: ='25 ABRIL (SABADO)'!M56 -> 677636.3 | M56: =K56+O56 -> 677636.3 | S56: =+S55 -> 8.5 | U56: =O56/(H56*60*S56)*100000 -> #DIV/0!
I57: 213 | K57: ='25 ABRIL (SABADO)'!M57 -> 633388.9 | M57: =K57+O57 -> 633388.9 | S57: =+S56 -> 8.5 | U57: =O57/(H57*60*S57)*100000 -> #DIV/0!
I58: 214 | K58: ='25 ABRIL (SABADO)'!M58 -> 657550.9 | M58: =K58+O58 -> 657550.9 | S58: =+S57 -> 8.5 | U58: =O58/(H58*60*S58)*100000 -> #DIV/0!
I59: 215 | K59: ='25 ABRIL (SABADO)'!M59 -> 694890.2 | M59: =K59+O59 -> 694890.2 | S59: =+S58 -> 8.5 | U59: =O59/(H59*60*S59)*100000 -> #DIV/0!
U61: =AVERAGE(U51:U59) -> #DIV/0! | W61: =AVERAGE(W51:W58) -> #DIV/0!
G63: Mínimo | H63: Máximo
...

Sheet 25 ABRIL (SABADO)
A2: =TODAY()-1 -> 46133
I4: Turno | K4: Jaq | M4: Smit | O4: 300 | Q4: Karl M
I5: 1ro. | K5: =U43 -> #DIV/0! | M5: =U61 -> #DIV/0! | O5: =U92 -> #DIV/0! | Q5: =U103 -> #DIV/0!
A7: RESUMEN DE EFICIENCIAS | I7: 2do. | K7: =U132 -> #DIV/0! | M7: =U150 -> #DIV/0! | O7: =U181 -> #DIV/0! | Q7: =U192 -> #DIV/0!
I9: 3er | K9: =+U221 -> #DIV/0! | M9: =+U239 -> #DIV/0! | O9: =+U270 -> #DIV/0! | Q9: =U281 -> #DIV/0!
I11: 4to. | K11: =+U310 -> 0 | M11: =+U328 -> 0 | O11: =+U359 -> 0 | Q11: =U343 -> 0
H13: Promedio | K13: =(K11+K9+K7+K5)/3 -> #DIV/0! | M13: =(M11+M9+M7+M5)/3 -> #DIV/0! | O13: =(O11+O9+O7+O5)/3 -> #DIV/0! | Q13: =(Q11+Q9+Q7+Q5)/3 -> #DIV/0!
A18: PRIMER TURNO PRIMER TURNO PRIMER TURNO
A19: 1 TURNO | B19: HORARIO: | K19: SUPERVISOR: | R19: DIA: | W19: FECHA:
A21: COMENTARIO DE PERSONAL
A25: F=FALTA, P=PERMISO, R=RETARDO, C=CASTIGO, I=INCAPACIDAD, V=VACACIONES, FL=FESTIVO LABORADO, FD=FESTIVO DESCANSADO, CL=CAMBIO DE LUGAR, B=BAJA, CT=CAMBIO DE TURNO
A27: Observaciones:
G30: Mínimo | H30: Máximo
A31: JACQUARD | B31: TEMPERATURA | G31: ='24 ABRIL (VIERNES)'!G31 -> 20 | H31: ='24 ABRIL (VIERNES)'!H31 -> 29 | Q31: =AVERAGE(K31,M31,O31) -> #DIV/0! | V31: =AVERAGE(S36:S41) -> 8.5
A32: SULZER | B32: HUMEDAD | G32: ='24 ABRIL (VIERNES)'!G32 -> 60 | H32: ='24 ABRIL (VIERNES)'!H32 -> 75 | Q32: =AVERAGE(K32,M32,O32) -> #DIV/0! | S32: MAQUINAS TRABAJANDO | V32: =COUNT(S36:S41) -> 6
K34: Marcador | M34: Marcador | O34: Marcas | S34: Horas | U34: Eficiencia | W34: Temp.
A35: Observaciones | B35: R | C35: P | D35: L | E35: tiempo | H35: vel | I35: telar | K35: Inicial | M35: Final | S35: 8.5
I36: 207 | K36: ='24 ABRIL (VIERNES)'!M36 -> 553941 | M36: =K36+O36 -> 553941 | S36: =+S35 -> 8.5 | U36: =O36/(H36*60*S36)*100000 -> #DIV/0!
I37: 208 | K37: ='24 ABRIL (VIERNES)'!M37 -> 617577 | M37: =K37+O37 -> 617577 | S37: =+S36 -> 8.5 | U37: =O37/(H37*60*S37)*100000 -> #DIV/0!
I38: 209 | K38: ='24 ABRIL (VIERNES)'!M38 -> 595396 | M38: =K38+O38 -> 595396 | S38: =+S37 -> 8.5 | U38: =O38/(H38*60*S38)*100000 -> #DIV/0!
I39: 210 | K39: ='24 ABRIL (VIERNES)'!M39 -> 682073.4 | M39: =K39+O39 -> 682073.4 | S39: =+S38 -> 8.5 | U39: =O39/(H39*60*S39)*100000 -> #DIV/0!
I40: 211 | K40: ='24 ABRIL (VIERNES)'!M40 -> 739209.5 | M40: =K40+O40 -> 739209.5 | S40: =+S39 -> 8.5 | U40: =O40/(H40*60*S40)*100000 -> #DIV/0!
I41: 212 | K41: ='24 ABRIL (VIERNES)'!M41 -> 0 | M41: =K41+O41 -> 0 | S41: =+S40 -> 8.5 | U41: =O41/(H41*60*S41)*100000 -> #DIV/0!
U43: =AVERAGE(U36:U41) -> #DIV/0! | W43: =AVERAGE(W36:W41) -> #DIV/0!
G45: Mínimo | H45: Máximo
A46: JACQUARD | B46: TEMPERATURA | G46: =$G$31 -> 20 | H46: =$H$31 -> 29 | Q46: =AVERAGE(K46,M46,O46) -> #DIV/0! | V46: =AVERAGE(S51:S59) -> 8.5
A47: SMIT | B47: HUMEDAD | G47: =$G$32 -> 60 | H47: =$H$32 -> 75 | Q47: =AVERAGE(K47,M47,O47) -> #DIV/0! | S47: MAQUINAS TRABAJANDO | V47: =COUNT(S51:S59) -> 9
K49: Marcador | M49: Marcador | O49: Marcas | S49: Horas | U49: Eficiencia | W49: Temp.
A50: Observaciones | B50: R | C50: P | D50: L | E50: tiempo | H50: vel | I50: telar | K50: Inicial | M50: Final | S50: 8.5
I51: 201 | K51: ='24 ABRIL (VIERNES)'!M51 -> 647180.6 | M51: =K51+O51 -> 647180.6 | S51: =+S50 -> 8.5 | U51: =O51/(H51*60*S51)*100000 -> #DIV/0!
I52: 202 | K52: ='24 ABRIL (VIERNES)'!M52 -> 753490.7 | M52: =K52+O52 -> 753490.7 | S52: =+S51 -> 8.5 | U52: =O52/(H52*60*S52)*100000 -> #DIV/0!
I53: 203 | K53: ='24 ABRIL (VIERNES)'!M53 -> 654637.8 | M53: =K53+O53 -> 654637.8 | S53: =+S52 -> 8.5 | U53: =O53/(H53*60*S53)*100000 -> #DIV/0!
I54: 204 | K54: ='24 ABRIL (VIERNES)'!M54 -> 662768.7 | M54: =K54+O54 -> 662768.7 | S54: =+S53 -> 8.5 | U54: =O54/(H54*60*S54)*100000 -> #DIV/0!
I55: 205 | K55: ='24 ABRIL (VIERNES)'!M55 -> 647848.7 | M55: =K55+O55 -> 647848.7 | S55: =+S54 -> 8.5 | U55: =O55/(H55*60*S55)*100000 -> #DIV/0!
I56: 206 | K56: ='24 ABRIL (VIERNES)'!M56 -> 677636.3 | M56: =K56+O56 -> 677636.3 | S56: =+S55 -> 8.5 | U56: =O56/(H56*60*S56)*100000 -> #DIV/0!
I57: 213 | K57: ='24 ABRIL (VIERNES)'!M57 -> 633388.9 | M57: =K57+O57 -> 633388.9 | S57: =+S56 -> 8.5 | U57: =O57/(H57*60*S57)*100000 -> #DIV/0!
I58: 214 | K58: ='24 ABRIL (VIERNES)'!M58 -> 657550.9 | M58: =K58+O58 -> 657550.9 | S58: =+S57 -> 8.5 | U58: =O58/(H58*60*S58)*100000 -> #DIV/0!
I59: 215 | K59: ='24 ABRIL (VIERNES)'!M59 -> 694890.2 | M59: =K59+O59 -> 694890.2 | S59: =+S58 -> 8.5 | U59: =O59/(H59*60*S59)*100000 -> #DIV/0!
U61: =AVERAGE(U51:U59) -> #DIV/0! | W61: =AVERAGE(W51:W58) -> #DIV/0!
G63: Mínimo | H63: Máximo
...

Sheet 24 ABRIL (VIERNES)
A2: =TODAY()-1 -> 46133
I4: Turno | K4: Jaq | M4: Smit | O4: 300 | Q4: Karl M
I5: 1ro. | K5: =U43 -> #DIV/0! | M5: =U61 -> #DIV/0! | O5: =U92 -> #DIV/0! | Q5: =U103 -> #DIV/0!
A7: RESUMEN DE EFICIENCIAS | I7: 2do. | K7: =U132 -> #DIV/0! | M7: =U150 -> #DIV/0! | O7: =U181 -> #DIV/0! | Q7: =U192 -> #DIV/0!
I9: 3er | K9: =+U221 -> #DIV/0! | M9: =+U239 -> #DIV/0! | O9: =+U270 -> #DIV/0! | Q9: =U281 -> #DIV/0!
I11: 4to. | K11: =+U310 -> 0 | M11: =+U328 -> 0 | O11: =+U359 -> 0 | Q11: =U343 -> 0
H13: Promedio | K13: =(K11+K9+K7+K5)/3 -> #DIV/0! | M13: =(M11+M9+M7+M5)/3 -> #DIV/0! | O13: =(O11+O9+O7+O5)/3 -> #DIV/0! | Q13: =(Q11+Q9+Q7+Q5)/3 -> #DIV/0!
A18: PRIMER TURNO PRIMER TURNO PRIMER TURNO
A19: 1 TURNO | B19: HORARIO: | K19: SUPERVISOR: | R19: DIA: | W19: FECHA:
A21: COMENTARIO DE PERSONAL
A25: F=FALTA, P=PERMISO, R=RETARDO, C=CASTIGO, I=INCAPACIDAD, V=VACACIONES, FL=FESTIVO LABORADO, FD=FESTIVO DESCANSADO, CL=CAMBIO DE LUGAR, B=BAJA, CT=CAMBIO DE TURNO
A27: Observaciones:
G30: Mínimo | H30: Máximo
A31: JACQUARD | B31: TEMPERATURA | G31: ='23 ABRIL (JUEVES)'!G31 -> 20 | H31: ='23 ABRIL (JUEVES)'!H31 -> 29 | Q31: =AVERAGE(K31,M31,O31) -> #DIV/0! | V31: =AVERAGE(S36:S41) -> 8.5
A32: SULZER | B32: HUMEDAD | G32: ='23 ABRIL (JUEVES)'!G32 -> 60 | H32: ='23 ABRIL (JUEVES)'!H32 -> 75 | Q32: =AVERAGE(K32,M32,O32) -> #DIV/0! | S32: MAQUINAS TRABAJANDO | V32: =COUNT(S36:S41) -> 6
K34: Marcador | M34: Marcador | O34: Marcas | S34: Horas | U34: Eficiencia | W34: Temp.
A35: Observaciones | B35: R | C35: P | D35: L | E35: tiempo | H35: vel | I35: telar | K35: Inicial | M35: Final | S35: 8.5
I36: 207 | K36: ='23 ABRIL (JUEVES)'!M36 -> 553941 | M36: =K36+O36 -> 553941 | S36: =+S35 -> 8.5 | U36: =O36/(H36*60*S36)*100000 -> #DIV/0!
I37: 208 | K37: ='23 ABRIL (JUEVES)'!M37 -> 617577 | M37: =K37+O37 -> 617577 | S37: =+S36 -> 8.5 | U37: =O37/(H37*60*S37)*100000 -> #DIV/0!
I38: 209 | K38: ='23 ABRIL (JUEVES)'!M38 -> 595396 | M38: =K38+O38 -> 595396 | S38: =+S37 -> 8.5 | U38: =O38/(H38*60*S38)*100000 -> #DIV/0!
I39: 210 | K39: ='23 ABRIL (JUEVES)'!M39 -> 682073.4 | M39: =K39+O39 -> 682073.4 | S39: =+S38 -> 8.5 | U39: =O39/(H39*60*S39)*100000 -> #DIV/0!
I40: 211 | K40: ='23 ABRIL (JUEVES)'!M40 -> 739209.5 | M40: =K40+O40 -> 739209.5 | S40: =+S39 -> 8.5 | U40: =O40/(H40*60*S40)*100000 -> #DIV/0!
I41: 212 | K41: ='23 ABRIL (JUEVES)'!M41 -> 0 | M41: =K41+O41 -> 0 | S41: =+S40 -> 8.5 | U41: =O41/(H41*60*S41)*100000 -> #DIV/0!
U43: =AVERAGE(U36:U41) -> #DIV/0! | W43: =AVERAGE(W36:W41) -> #DIV/0!
G45: Mínimo | H45: Máximo
A46: JACQUARD | B46: TEMPERATURA | G46: =$G$31 -> 20 | H46: =$H$31 -> 29 | Q46: =AVERAGE(K46,M46,O46) -> #DIV/0! | V46: =AVERAGE(S51:S59) -> 8.5
A47: SMIT | B47: HUMEDAD | G47: =$G$32 -> 60 | H47: =$H$32 -> 75 | Q47: =AVERAGE(K47,M47,O47) -> #DIV/0! | S47: MAQUINAS TRABAJANDO | V47: =COUNT(S51:S59) -> 9
K49: Marcador | M49: Marcador | O49: Marcas | S49: Horas | U49: Eficiencia | W49: Temp.
A50: Observaciones | B50: R | C50: P | D50: L | E50: tiempo | H50: vel | I50: telar | K50: Inicial | M50: Final | S50: 8.5
I51: 201 | K51: ='23 ABRIL (JUEVES)'!M51 -> 647180.6 | M51: =K51+O51 -> 647180.6 | S51: =+S50 -> 8.5 | U51: =O51/(H51*60*S51)*100000 -> #DIV/0!
I52: 202 | K52: ='23 ABRIL (JUEVES)'!M52 -> 753490.7 | M52: =K52+O52 -> 753490.7 | S52: =+S51 -> 8.5 | U52: =O52/(H52*60*S52)*100000 -> #DIV/0!
I53: 203 | K53: ='23 ABRIL (JUEVES)'!M53 -> 654637.8 | M53: =K53+O53 -> 654637.8 | S53: =+S52 -> 8.5 | U53: =O53/(H53*60*S53)*100000 -> #DIV/0!
I54: 204 | K54: ='23 ABRIL (JUEVES)'!M54 -> 662768.7 | M54: =K54+O54 -> 662768.7 | S54: =+S53 -> 8.5 | U54: =O54/(H54*60*S54)*100000 -> #DIV/0!
I55: 205 | K55: ='23 ABRIL (JUEVES)'!M55 -> 647848.7 | M55: =K55+O55 -> 647848.7 | S55: =+S54 -> 8.5 | U55: =O55/(H55*60*S55)*100000 -> #DIV/0!
I56: 206 | K56: ='23 ABRIL (JUEVES)'!M56 -> 677636.3 | M56: =K56+O56 -> 677636.3 | S56: =+S55 -> 8.5 | U56: =O56/(H56*60*S56)*100000 -> #DIV/0!
I57: 213 | K57: ='23 ABRIL (JUEVES)'!M57 -> 633388.9 | M57: =K57+O57 -> 633388.9 | S57: =+S56 -> 8.5 | U57: =O57/(H57*60*S57)*100000 -> #DIV/0!
I58: 214 | K58: ='23 ABRIL (JUEVES)'!M58 -> 657550.9 | M58: =K58+O58 -> 657550.9 | S58: =+S57 -> 8.5 | U58: =O58/(H58*60*S58)*100000 -> #DIV/0!
I59: 215 | K59: ='23 ABRIL (JUEVES)'!M59 -> 694890.2 | M59: =K59+O59 -> 694890.2 | S59: =+S58 -> 8.5 | U59: =O59/(H59*60*S59)*100000 -> #DIV/0!
U61: =AVERAGE(U51:U59) -> #DIV/0! | W61: =AVERAGE(W51:W58) -> #DIV/0!
G63: Mínimo | H63: Máximo
...

Sheet 23 ABRIL (JUEVES)
A2: =TODAY()-1 -> 46133
I4: Turno | K4: Jaq | M4: Smit | O4: 300 | Q4: Karl M
I5: 1ro. | K5: =U43 -> #DIV/0! | M5: =U61 -> #DIV/0! | O5: =U92 -> #DIV/0! | Q5: =U103 -> #DIV/0!
A7: RESUMEN DE EFICIENCIAS | I7: 2do. | K7: =U132 -> #DIV/0! | M7: =U150 -> #DIV/0! | O7: =U181 -> #DIV/0! | Q7: =U192 -> #DIV/0!
I9: 3er | K9: =+U221 -> #DIV/0! | M9: =+U239 -> #DIV/0! | O9: =+U270 -> #DIV/0! | Q9: =U281 -> #DIV/0!
I11: 4to. | K11: =+U310 -> 0 | M11: =+U328 -> 0 | O11: =+U359 -> 0 | Q11: =U343 -> 0
H13: Promedio | K13: =(K11+K9+K7+K5)/3 -> #DIV/0! | M13: =(M11+M9+M7+M5)/3 -> #DIV/0! | O13: =(O11+O9+O7+O5)/3 -> #DIV/0! | Q13: =(Q11+Q9+Q7+Q5)/3 -> #DIV/0!
A18: PRIMER TURNO PRIMER TURNO PRIMER TURNO
A19: 1 TURNO | B19: HORARIO: | K19: SUPERVISOR: | R19: DIA: | W19: FECHA:
A21: COMENTARIO DE PERSONAL
A25: F=FALTA, P=PERMISO, R=RETARDO, C=CASTIGO, I=INCAPACIDAD, V=VACACIONES, FL=FESTIVO LABORADO, FD=FESTIVO DESCANSADO, CL=CAMBIO DE LUGAR, B=BAJA, CT=CAMBIO DE TURNO
A27: Observaciones:
G30: Mínimo | H30: Máximo
A31: JACQUARD | B31: TEMPERATURA | G31: ='22 ABRIL (MIERCOLES)'!G31 -> 20 | H31: ='22 ABRIL (MIERCOLES)'!H31 -> 29 | Q31: =AVERAGE(K31,M31,O31) -> #DIV/0! | V31: =AVERAGE(S36:S41) -> 8.5
A32: SULZER | B32: HUMEDAD | G32: ='22 ABRIL (MIERCOLES)'!G32 -> 60 | H32: ='22 ABRIL (MIERCOLES)'!H32 -> 75 | Q32: =AVERAGE(K32,M32,O32) -> #DIV/0! | S32: MAQUINAS TRABAJANDO | V32: =COUNT(S36:S41) -> 6
K34: Marcador | M34: Marcador | O34: Marcas | S34: Horas | U34: Eficiencia | W34: Temp.
A35: Observaciones | B35: R | C35: P | D35: L | E35: tiempo | H35: vel | I35: telar | K35: Inicial | M35: Final | S35: 8.5
I36: 207 | K36: ='22 ABRIL (MIERCOLES)'!M36 -> 553941 | M36: =K36+O36 -> 553941 | S36: =+S35 -> 8.5 | U36: =O36/(H36*60*S36)*100000 -> #DIV/0!
I37: 208 | K37: ='22 ABRIL (MIERCOLES)'!M37 -> 617577 | M37: =K37+O37 -> 617577 | S37: =+S36 -> 8.5 | U37: =O37/(H37*60*S37)*100000 -> #DIV/0!
I38: 209 | K38: ='22 ABRIL (MIERCOLES)'!M38 -> 595396 | M38: =K38+O38 -> 595396 | S38: =+S37 -> 8.5 | U38: =O38/(H38*60*S38)*100000 -> #DIV/0!
I39: 210 | K39: ='22 ABRIL (MIERCOLES)'!M39 -> 682073.4 | M39: =K39+O39 -> 682073.4 | S39: =+S38 -> 8.5 | U39: =O39/(H39*60*S39)*100000 -> #DIV/0!
I40: 211 | K40: ='22 ABRIL (MIERCOLES)'!M40 -> 739209.5 | M40: =K40+O40 -> 739209.5 | S40: =+S39 -> 8.5 | U40: =O40/(H40*60*S40)*100000 -> #DIV/0!
I41: 212 | K41: ='22 ABRIL (MIERCOLES)'!M41 -> 0 | M41: =K41+O41 -> 0 | S41: =+S40 -> 8.5 | U41: =O41/(H41*60*S41)*100000 -> #DIV/0!
U43: =AVERAGE(U36:U41) -> #DIV/0! | W43: =AVERAGE(W36:W41) -> #DIV/0!
G45: Mínimo | H45: Máximo
A46: JACQUARD | B46: TEMPERATURA | G46: =$G$31 -> 20 | H46: =$H$31 -> 29 | Q46: =AVERAGE(K46,M46,O46) -> #DIV/0! | V46: =AVERAGE(S51:S59) -> 8.5
A47: SMIT | B47: HUMEDAD | G47: =$G$32 -> 60 | H47: =$H$32 -> 75 | Q47: =AVERAGE(K47,M47,O47) -> #DIV/0! | S47: MAQUINAS TRABAJANDO | V47: =COUNT(S51:S59) -> 9
K49: Marcador | M49: Marcador | O49: Marcas | S49: Horas | U49: Eficiencia | W49: Temp.
A50: Observaciones | B50: R | C50: P | D50: L | E50: tiempo | H50: vel | I50: telar | K50: Inicial | M50: Final | S50: 8.5
I51: 201 | K51: ='22 ABRIL (MIERCOLES)'!M51 -> 647180.6 | M51: =K51+O51 -> 647180.6 | S51: =+S50 -> 8.5 | U51: =O51/(H51*60*S51)*100000 -> #DIV/0!
I52: 202 | K52: ='22 ABRIL (MIERCOLES)'!M52 -> 753490.7 | M52: =K52+O52 -> 753490.7 | S52: =+S51 -> 8.5 | U52: =O52/(H52*60*S52)*100000 -> #DIV/0!
I53: 203 | K53: ='22 ABRIL (MIERCOLES)'!M53 -> 654637.8 | M53: =K53+O53 -> 654637.8 | S53: =+S52 -> 8.5 | U53: =O53/(H53*60*S53)*100000 -> #DIV/0!
I54: 204 | K54: ='22 ABRIL (MIERCOLES)'!M54 -> 662768.7 | M54: =K54+O54 -> 662768.7 | S54: =+S53 -> 8.5 | U54: =O54/(H54*60*S54)*100000 -> #DIV/0!
I55: 205 | K55: ='22 ABRIL (MIERCOLES)'!M55 -> 647848.7 | M55: =K55+O55 -> 647848.7 | S55: =+S54 -> 8.5 | U55: =O55/(H55*60*S55)*100000 -> #DIV/0!
I56: 206 | K56: ='22 ABRIL (MIERCOLES)'!M56 -> 677636.3 | M56: =K56+O56 -> 677636.3 | S56: =+S55 -> 8.5 | U56: =O56/(H56*60*S56)*100000 -> #DIV/0!
I57: 213 | K57: ='22 ABRIL (MIERCOLES)'!M57 -> 633388.9 | M57: =K57+O57 -> 633388.9 | S57: =+S56 -> 8.5 | U57: =O57/(H57*60*S57)*100000 -> #DIV/0!
I58: 214 | K58: ='22 ABRIL (MIERCOLES)'!M58 -> 657550.9 | M58: =K58+O58 -> 657550.9 | S58: =+S57 -> 8.5 | U58: =O58/(H58*60*S58)*100000 -> #DIV/0!
I59: 215 | K59: ='22 ABRIL (MIERCOLES)'!M59 -> 694890.2 | M59: =K59+O59 -> 694890.2 | S59: =+S58 -> 8.5 | U59: =O59/(H59*60*S59)*100000 -> #DIV/0!
U61: =AVERAGE(U51:U59) -> #DIV/0! | W61: =AVERAGE(W51:W58) -> #DIV/0!
G63: Mínimo | H63: Máximo
...

Sheet 22 ABRIL (MIERCOLES)
A2: =TODAY()-1 -> 46133
I4: Turno | K4: Jaq | M4: Smit | O4: 300 | Q4: Karl M
I5: 1ro. | K5: =U43 -> #DIV/0! | M5: =U61 -> 0 | O5: =U92 -> 0 | Q5: =U103 -> #DIV/0!
A7: RESUMEN DE EFICIENCIAS | I7: 2do. | K7: =U132 -> #DIV/0! | M7: =U150 -> #DIV/0! | O7: =U181 -> #DIV/0! | Q7: =U192 -> #DIV/0!
I9: 3er | K9: =+U221 -> #DIV/0! | M9: =+U239 -> #DIV/0! | O9: =+U270 -> #DIV/0! | Q9: =U281 -> #DIV/0!
I11: 4to. | K11: =+U310 -> 0 | M11: =+U328 -> 0 | O11: =+U359 -> 0 | Q11: =U343 -> 0
H13: Promedio | K13: =(K11+K9+K7+K5)/3 -> #DIV/0! | M13: =(M11+M9+M7+M5)/3 -> #DIV/0! | O13: =(O11+O9+O7+O5)/3 -> #DIV/0! | Q13: =(Q11+Q9+Q7+Q5)/3 -> #DIV/0!
A18: PRIMER TURNO PRIMER TURNO PRIMER TURNO
A19: 1 TURNO | B19: HORARIO: | G19: 6:30-14:30 | K19: SUPERVISOR: | N19: DANIEL VALTIERRA | R19: DIA: | S19: MIERCOLES | W19: FECHA: | Y19: 46134
A21: COMENTARIO DE PERSONAL
A25: F=FALTA, P=PERMISO, R=RETARDO, C=CASTIGO, I=INCAPACIDAD, V=VACACIONES, FL=FESTIVO LABORADO, FD=FESTIVO DESCANSADO, CL=CAMBIO DE LUGAR, B=BAJA, CT=CAMBIO DE TURNO
A27: Observaciones: | B27: 8 H T-208 EN ESPERA DE REFACCIÓN, H T-209 ATADO ESPECIAL,
G30: Mínimo | H30: Máximo
A31: JACQUARD | B31: TEMPERATURA | G31: ='21 ABRIL (MARTES)'!G31 -> 20 | H31: ='21 ABRIL (MARTES)'!H31 -> 29 | Q31: =AVERAGE(K31,M31,O31) -> #DIV/0! | V31: =AVERAGE(S36:S41) -> 8
A32: SULZER | B32: HUMEDAD | G32: ='21 ABRIL (MARTES)'!G32 -> 60 | H32: ='21 ABRIL (MARTES)'!H32 -> 75 | Q32: =AVERAGE(K32,M32,O32) -> #DIV/0! | S32: MAQUINAS TRABAJANDO | V32: =COUNT(S36:S41) -> 6
K34: Marcador | M34: Marcador | O34: Marcas | S34: Horas | U34: Eficiencia | W34: Temp.
A35: Observaciones | B35: R | C35: P | D35: L | E35: tiempo | H35: vel | I35: telar | K35: Inicial | M35: Final | S35: 8
H36: 280 | I36: 207 | K36: ='21 ABRIL (MARTES)'!M36 -> 553941 | M36: =K36+O36 -> 553941 | S36: =+S35 -> 8 | U36: =O36/(H36*60*S36)*100000 -> 0
A37: EN ESPERA DE REFACCIÓN | H37: 300 | I37: 208 | K37: ='21 ABRIL (MARTES)'!M37 -> 617577 | M37: =K37+O37 -> 617577 | S37: =+S36 -> 8 | U37: =O37/(H37*60*S37)*100000 -> 0
A38: ATADO RIZO ESPECIAL | B38: 1 | H38: 300 | I38: 209 | K38: ='21 ABRIL (MARTES)'!M38 -> 595396 | M38: =K38+O38 -> 595396 | S38: =+S37 -> 8 | U38: =O38/(H38*60*S38)*100000 -> 0
H39: 290 | I39: 210 | K39: ='21 ABRIL (MARTES)'!M39 -> 682073.4 | M39: =K39+O39 -> 682073.4 | S39: =+S38 -> 8 | U39: =O39/(H39*60*S39)*100000 -> 0
H40: 290 | I40: 211 | K40: ='21 ABRIL (MARTES)'!M40 -> 739209.5 | M40: =K40+O40 -> 739209.5 | S40: =+S39 -> 8 | U40: =O40/(H40*60*S40)*100000 -> 0
I41: 212 | K41: ='21 ABRIL (MARTES)'!M41 -> 0 | M41: =K41+O41 -> 0 | S41: =+S40 -> 8 | U41: =O41/(H41*60*S41)*100000 -> #DIV/0!
U43: =AVERAGE(U36:U41) -> #DIV/0! | W43: =AVERAGE(W36:W41) -> #DIV/0!
G45: Mínimo | H45: Máximo
A46: JACQUARD | B46: TEMPERATURA | G46: =$G$31 -> 20 | H46: =$H$31 -> 29 | Q46: =AVERAGE(K46,M46,O46) -> #DIV/0! | V46: =AVERAGE(S51:S59) -> 8
A47: SMIT | B47: HUMEDAD | G47: =$G$32 -> 60 | H47: =$H$32 -> 75 | Q47: =AVERAGE(K47,M47,O47) -> #DIV/0! | S47: MAQUINAS TRABAJANDO | V47: =COUNT(S51:S59) -> 9
K49: Marcador | M49: Marcador | O49: Marcas | S49: Horas | U49: Eficiencia | W49: Temp.
A50: Observaciones | B50: R | C50: P | D50: L | E50: tiempo | H50: vel | I50: telar | K50: Inicial | M50: Final | S50: 8
A51: ATADO PIE | C51: 1 | H51: 286 | I51: 201 | K51: ='21 ABRIL (MARTES)'!M51 -> 647180.6 | M51: =K51+O51 -> 647180.6 | S51: =+S50 -> 8 | U51: =O51/(H51*60*S51)*100000 -> 0
H52: 271 | I52: 202 | K52: ='21 ABRIL (MARTES)'!M52 -> 753490.7 | M52: =K52+O52 -> 753490.7 | S52: =+S51 -> 8 | U52: =O52/(H52*60*S52)*100000 -> 0
A53: MUESTRAS | H53: 287 | I53: 203 | K53: ='21 ABRIL (MARTES)'!M53 -> 654637.8 | M53: =K53+O53 -> 654637.8 | S53: =+S52 -> 8 | U53: =O53/(H53*60*S53)*100000 -> 0
H54: 302 | I54: 204 | K54: ='21 ABRIL (MARTES)'!M54 -> 662768.7 | M54: =K54+O54 -> 662768.7 | S54: =+S53 -> 8 | U54: =O54/(H54*60*S54)*100000 -> 0
H55: 294 | I55: 205 | K55: ='21 ABRIL (MARTES)'!M55 -> 647848.7 | M55: =K55+O55 -> 647848.7 | S55: =+S54 -> 8 | U55: =O55/(H55*60*S55)*100000 -> 0
H56: 303 | I56: 206 | K56: ='21 ABRIL (MARTES)'!M56 -> 677636.3 | M56: =K56+O56 -> 677636.3 | S56: =+S55 -> 8 | U56: =O56/(H56*60*S56)*100000 -> 0
H57: 300 | I57: 213 | K57: ='21 ABRIL (MARTES)'!M57 -> 633388.9 | M57: =K57+O57 -> 633388.9 | S57: =+S56 -> 8 | U57: =O57/(H57*60*S57)*100000 -> 0
H58: 305 | I58: 214 | K58: ='21 ABRIL (MARTES)'!M58 -> 657550.9 | M58: =K58+O58 -> 657550.9 | S58: =+S57 -> 8 | U58: =O58/(H58*60*S58)*100000 -> 0
H59: 310 | I59: 215 | K59: ='21 ABRIL (MARTES)'!M59 -> 694890.2 | M59: =K59+O59 -> 694890.2 | S59: =+S58 -> 8 | U59: =O59/(H59*60*S59)*100000 -> 0
U61: =AVERAGE(U51:U59) -> 0 | W61: =AVERAGE(W51:W58) -> #DIV/0!
G63: Mínimo | H63: Máximo
...

Sheet 21 ABRIL (MARTES)
A2: =TODAY()-1 -> 46133
I4: Turno | K4: Jaq | M4: Smit | O4: 300 | Q4: Karl M
I5: 1ro. | K5: =U43 -> 83.760605 | M5: =U61 -> 80.868541 | O5: =U92 -> 78.702411 | Q5: =U103 -> 0
A7: RESUMEN DE EFICIENCIAS | I7: 2do. | K7: =U132 -> 81.067837 | M7: =U150 -> 71.980351 | O7: =U181 -> 81.111171 | Q7: =U192 -> 0
I9: 3er | K9: =+U221 -> 78.104475 | M9: =+U239 -> 84.887158 | O9: =+U270 -> 83.268551 | Q9: =U281 -> 0
I11: 4to. | K11: =+U310 -> 0 | M11: =+U328 -> 0 | O11: =+U359 -> 0 | Q11: =U343 -> 0
H13: Promedio | K13: =(K11+K9+K7+K5)/3 -> 80.977639 | M13: =(M11+M9+M7+M5)/3 -> 79.24535 | O13: =(O11+O9+O7+O5)/3 -> 81.027378 | Q13: =(Q11+Q9+Q7+Q5)/3 -> 0
A18: PRIMER TURNO PRIMER TURNO PRIMER TURNO
A19: 1 TURNO | B19: HORARIO: | G19: 6:30-14:30 | K19: SUPERVISOR: | N19: DANIEL VALTIERRA | R19: DIA: | S19: MARTES | W19: FECHA: | Y19: 46133
A21: COMENTARIO DE PERSONAL
A25: F=FALTA, P=PERMISO, R=RETARDO, C=CASTIGO, I=INCAPACIDAD, V=VACACIONES, FL=FESTIVO LABORADO, FD=FESTIVO DESCANSADO, CL=CAMBIO DE LUGAR, B=BAJA, CT=CAMBIO DE TURNO
A27: Observaciones: | B27: 6 H T-208 REFACIÓN, 4 hrs t-316 tiranteria
G30: Mínimo | H30: Máximo
A31: JACQUARD | B31: TEMPERATURA | G31: ='20 ABRIL (LUNES)'!G31 -> 20 | H31: ='20 ABRIL (LUNES)'!H31 -> 29 | Q31: =AVERAGE(K31,M31,O31) -> #DIV/0! | V31: =AVERAGE(S36:S41) -> 6.8
A32: SULZER | B32: HUMEDAD | G32: ='20 ABRIL (LUNES)'!G32 -> 60 | H32: ='20 ABRIL (LUNES)'!H32 -> 75 | Q32: =AVERAGE(K32,M32,O32) -> #DIV/0! | S32: MAQUINAS TRABAJANDO | V32: =COUNT(S36:S41) -> 5
K34: Marcador | M34: Marcador | O34: Marcas | S34: Horas | U34: Eficiencia | W34: Temp.
A35: Observaciones | B35: R | C35: P | D35: L | E35: tiempo | H35: vel | I35: telar | K35: Inicial | M35: Final | S35: 8
H36: 280 | I36: 207 | K36: ='20 ABRIL (LUNES)'!M36 -> 553840 | M36: =K36+O36 -> 553941 | O36: 101 | S36: =+S35 -> 8 | U36: =O36/(H36*60*S36)*100000 -> 75.14881
H37: 300 | I37: 208 | K37: ='20 ABRIL (LUNES)'!M37 -> 617547 | M37: =K37+O37 -> 617577 | O37: 30 | S37: 2 | U37: =O37/(H37*60*S37)*100000 -> 83.333333
H38: 300 | I38: 209 | K38: ='20 ABRIL (LUNES)'!M38 -> 595287 | M38: =K38+O38 -> 595396 | O38: 109 | S38: =+S35 -> 8 | U38: =O38/(H38*60*S38)*100000 -> 75.694444
H39: 290 | I39: 210 | K39: ='20 ABRIL (LUNES)'!M39 -> 681936.4 | M39: =K39+O39 -> 682073.4 | O39: 137 | S39: =+S38 -> 8 | U39: =O39/(H39*60*S39)*100000 -> 98.41954
H40: 290 | I40: 211 | K40: ='20 ABRIL (LUNES)'!M40 -> 739089.5 | M40: =K40+O40 -> 739209.5 | O40: 120 | S40: =+S39 -> 8 | U40: =O40/(H40*60*S40)*100000 -> 86.206897
U43: =AVERAGE(U36:U41) -> 83.760605 | W43: =AVERAGE(W36:W41) -> #DIV/0!
G45: Mínimo | H45: Máximo
A46: JACQUARD | B46: TEMPERATURA | G46: =$G$31 -> 20 | H46: =$H$31 -> 29 | Q46: =AVERAGE(K46,M46,O46) -> #DIV/0! | V46: =AVERAGE(S51:S59) -> 8
A47: SMIT | B47: HUMEDAD | G47: =$G$32 -> 60 | H47: =$H$32 -> 75 | Q47: =AVERAGE(K47,M47,O47) -> #DIV/0! | S47: MAQUINAS TRABAJANDO | V47: =COUNT(S51:S59) -> 9
K49: Marcador | M49: Marcador | O49: Marcas | S49: Horas | U49: Eficiencia | W49: Temp.
A50: Observaciones | B50: R | C50: P | D50: L | E50: tiempo | H50: vel | I50: telar | K50: Inicial | M50: Final | S50: 8
H51: 286 | I51: 201 | K51: ='20 ABRIL (LUNES)'!M51 -> 647059.6 | M51: =K51+O51 -> 647180.6 | O51: 121 | S51: =+S50 -> 8 | U51: =O51/(H51*60*S51)*100000 -> 88.141026
H52: 271 | I52: 202 | K52: ='20 ABRIL (LUNES)'!M52 -> 753407.7 | M52: =K52+O52 -> 753490.7 | O52: 83 | S52: =+S51 -> 8 | U52: =O52/(H52*60*S52)*100000 -> 63.806888
H53: 287 | I53: 203 | K53: ='20 ABRIL (LUNES)'!M53 -> 654526.8 | M53: =K53+O53 -> 654637.8 | O53: 111 | S53: =+S52 -> 8 | U53: =O53/(H53*60*S53)*100000 -> 80.574913
H54: 302 | I54: 204 | K54: ='20 ABRIL (LUNES)'!M54 -> 662652.7 | M54: =K54+O54 -> 662768.7 | O54: 116 | S54: =+S53 -> 8 | U54: =O54/(H54*60*S54)*100000 -> 80.022075
H55: 294 | I55: 205 | K55: ='20 ABRIL (LUNES)'!M55 -> 647728.7 | M55: =K55+O55 -> 647848.7 | O55: 120 | S55: =+S54 -> 8 | U55: =O55/(H55*60*S55)*100000 -> 85.034014
H56: 303 | I56: 206 | K56: ='20 ABRIL (LUNES)'!M56 -> 677520.3 | M56: =K56+O56 -> 677636.3 | O56: 116 | S56: =+S55 -> 8 | U56: =O56/(H56*60*S56)*100000 -> 79.757976
H57: 300 | I57: 213 | K57: ='20 ABRIL (LUNES)'!M57 -> 633281.9 | M57: =K57+O57 -> 633388.9 | O57: 107 | S57: =+S56 -> 8 | U57: =O57/(H57*60*S57)*100000 -> 74.305556
H58: 305 | I58: 214 | K58: ='20 ABRIL (LUNES)'!M58 -> 657419.9 | M58: =K58+O58 -> 657550.9 | O58: 131 | S58: =+S57 -> 8 | U58: =O58/(H58*60*S58)*100000 -> 89.480874
H59: 310 | I59: 215 | K59: ='20 ABRIL (LUNES)'!M59 -> 694761.2 | M59: =K59+O59 -> 694890.2 | O59: 129 | S59: =+S58 -> 8 | U59: =O59/(H59*60*S59)*100000 -> 86.693548
U61: =AVERAGE(U51:U59) -> 80.868541 | W61: =AVERAGE(W51:W58) -> #DIV/0!
G63: Mínimo | H63: Máximo
A64: SMIT LISO | B64: TEMPERATURA | G64: =$G$31 -> 20 | H64: =$H$31 -> 29 | Q64: =AVERAGE(K64,M64,O64) -> #DIV/0! | V64: =AVERAGE(S69:S90) -> 7.8181818
...

Sheet 20 ABRIL (LUNES)
A2: =TODAY()-1 -> 46133
I4: Turno | K4: Jaq | M4: Smit | O4: 300 | Q4: Karl M
I5: 1ro. | K5: =U43 -> 82.110359 | M5: =U61 -> 81.477959 | O5: =U92 -> 78.806465 | Q5: =U103 -> 0
A7: RESUMEN DE EFICIENCIAS | I7: 2do. | K7: =U132 -> 76.969759 | M7: =U150 -> 85.713768 | O7: =U181 -> 74.88394 | Q7: =U192 -> 0
I9: 3er | K9: =+U221 -> 83.531062 | M9: =+U239 -> 80.688243 | O9: =+U270 -> 82.039251 | Q9: =U281 -> 0
I11: 4to. | K11: =+U310 -> 0 | M11: =+U328 -> 0 | O11: =+U359 -> 0 | Q11: =U343 -> 0
H13: Promedio | K13: =(K11+K9+K7+K5)/3 -> 80.870393 | M13: =(M11+M9+M7+M5)/3 -> 82.626657 | O13: =(O11+O9+O7+O5)/3 -> 78.576552 | Q13: =(Q11+Q9+Q7+Q5)/3 -> 0
A18: PRIMER TURNO PRIMER TURNO PRIMER TURNO
A19: 1 TURNO | B19: HORARIO: | G19: 6:30-14:30 | K19: SUPERVISOR: | N19: DANIEL VALTIERRA | R19: DIA: | S19: LUNES | W19: FECHA: | Y19: 46132
A21: COMENTARIO DE PERSONAL
A25: F=FALTA, P=PERMISO, R=RETARDO, C=CASTIGO, I=INCAPACIDAD, V=VACACIONES, FL=FESTIVO LABORADO, FD=FESTIVO DESCANSADO, CL=CAMBIO DE LUGAR, B=BAJA, CT=CAMBIO DE TURNO
A27: Observaciones: | B27: 3 HRS T-312, 5 H T-318 AJUSTE CALIDAD, 8 H T316 CORRECTIVO TIRANTERÍA,
G30: Mínimo | H30: Máximo
A31: JACQUARD | B31: TEMPERATURA | G31: ='19 ABRIL (DOMINGO)'!G31 -> 20 | H31: ='19 ABRIL (DOMINGO)'!H31 -> 29 | Q31: =AVERAGE(K31,M31,O31) -> #DIV/0! | V31: =AVERAGE(S36:S41) -> 8
A32: SULZER | B32: HUMEDAD | G32: ='19 ABRIL (DOMINGO)'!G32 -> 60 | H32: ='19 ABRIL (DOMINGO)'!H32 -> 75 | Q32: =AVERAGE(K32,M32,O32) -> #DIV/0! | S32: MAQUINAS TRABAJANDO | V32: =COUNT(S36:S41) -> 5
K34: Marcador | M34: Marcador | O34: Marcas | S34: Horas | U34: Eficiencia | W34: Temp.
A35: Observaciones | B35: R | C35: P | D35: L | E35: tiempo | H35: vel | I35: telar | K35: Inicial | M35: Final | S35: 8
H36: 280 | I36: 207 | K36: ='19 ABRIL (DOMINGO)'!M36 -> 553747 | M36: =K36+O36 -> 553840 | O36: 93 | S36: =+S35 -> 8 | U36: =O36/(H36*60*S36)*100000 -> 69.196429
A37: FE MOTOR | H37: 300 | I37: 208 | K37: ='19 ABRIL (DOMINGO)'!M37 -> 617432 | M37: =K37+O37 -> 617547 | O37: 115 | S37: =+S36 -> 8 | U37: =O37/(H37*60*S37)*100000 -> 79.861111
A38: ATADO RIZO | B38: 1 | H38: 300 | I38: 209 | K38: ='19 ABRIL (DOMINGO)'!M38 -> 595167 | M38: =K38+O38 -> 595287 | O38: 120 | S38: =+S37 -> 8 | U38: =O38/(H38*60*S38)*100000 -> 83.333333
H39: 290 | I39: 210 | K39: ='19 ABRIL (DOMINGO)'!M39 -> 681806.4 | M39: =K39+O39 -> 681936.4 | O39: 130 | S39: =+S38 -> 8 | U39: =O39/(H39*60*S39)*100000 -> 93.390805
H40: 290 | I40: 211 | K40: ='19 ABRIL (DOMINGO)'!M40 -> 738971.5 | M40: =K40+O40 -> 739089.5 | O40: 118 | S40: =+S39 -> 8 | U40: =O40/(H40*60*S40)*100000 -> 84.770115
U43: =AVERAGE(U36:U41) -> 82.110359 | W43: =AVERAGE(W36:W41) -> #DIV/0!
G45: Mínimo | H45: Máximo
A46: JACQUARD | B46: TEMPERATURA | G46: =$G$31 -> 20 | H46: =$H$31 -> 29 | Q46: =AVERAGE(K46,M46,O46) -> #DIV/0! | V46: =AVERAGE(S51:S59) -> 8
A47: SMIT | B47: HUMEDAD | G47: =$G$32 -> 60 | H47: =$H$32 -> 75 | Q47: =AVERAGE(K47,M47,O47) -> #DIV/0! | S47: MAQUINAS TRABAJANDO | V47: =COUNT(S51:S59) -> 9
K49: Marcador | M49: Marcador | O49: Marcas | S49: Horas | U49: Eficiencia | W49: Temp.
A50: Observaciones | B50: R | C50: P | D50: L | E50: tiempo | H50: vel | I50: telar | K50: Inicial | M50: Final | S50: 8
H51: 286 | I51: 201 | K51: ='19 ABRIL (DOMINGO)'!M51 -> 646969.6 | M51: =K51+O51 -> 647059.6 | O51: 90 | S51: =+S50 -> 8 | U51: =O51/(H51*60*S51)*100000 -> 65.559441
H52: 271 | I52: 202 | K52: ='19 ABRIL (DOMINGO)'!M52 -> 753297.7 | M52: =K52+O52 -> 753407.7 | O52: 110 | S52: =+S51 -> 8 | U52: =O52/(H52*60*S52)*100000 -> 84.563346
H53: 287 | I53: 203 | K53: ='19 ABRIL (DOMINGO)'!M53 -> 654406.8 | M53: =K53+O53 -> 654526.8 | O53: 120 | S53: =+S52 -> 8 | U53: =O53/(H53*60*S53)*100000 -> 87.108014
H54: 302 | I54: 204 | K54: ='19 ABRIL (DOMINGO)'!M54 -> 662530.7 | M54: =K54+O54 -> 662652.7 | O54: 122 | S54: =+S53 -> 8 | U54: =O54/(H54*60*S54)*100000 -> 84.161148
H55: 294 | I55: 205 | K55: ='19 ABRIL (DOMINGO)'!M55 -> 647592.7 | M55: =K55+O55 -> 647728.7 | O55: 136 | S55: =+S54 -> 8 | U55: =O55/(H55*60*S55)*100000 -> 96.371882
H56: 303 | I56: 206 | K56: ='19 ABRIL (DOMINGO)'!M56 -> 677426.3 | M56: =K56+O56 -> 677520.3 | O56: 94 | S56: =+S55 -> 8 | U56: =O56/(H56*60*S56)*100000 -> 64.631463
A57: ATADO RIZO | B57: 1 | H57: 300 | I57: 213 | K57: ='19 ABRIL (DOMINGO)'!M57 -> 633183.9 | M57: =K57+O57 -> 633281.9 | O57: 98 | S57: =+S56 -> 8 | U57: =O57/(H57*60*S57)*100000 -> 68.055556
H58: 305 | I58: 214 | K58: ='19 ABRIL (DOMINGO)'!M58 -> 657292.9 | M58: =K58+O58 -> 657419.9 | O58: 127 | S58: =+S57 -> 8 | U58: =O58/(H58*60*S58)*100000 -> 86.748634
H59: 310 | I59: 215 | K59: ='19 ABRIL (DOMINGO)'!M59 -> 694618.2 | M59: =K59+O59 -> 694761.2 | O59: 143 | S59: =+S58 -> 8 | U59: =O59/(H59*60*S59)*100000 -> 96.102151
U61: =AVERAGE(U51:U59) -> 81.477959 | W61: =AVERAGE(W51:W58) -> #DIV/0!
G63: Mínimo | H63: Máximo
A64: SMIT LISO | B64: TEMPERATURA | G64: =$G$31 -> 20 | H64: =$H$31 -> 29 | Q64: =AVERAGE(K64,M64,O64) -> #DIV/0! | V64: =AVERAGE(S69:S90) -> 7.6190476
...

Sheet 19 ABRIL (DOMINGO)
A2: =TODAY()-1 -> 46133
I4: Turno | K4: Jaq | M4: Smit | O4: 300 | Q4: Karl M
I5: 1ro. | K5: =U43 -> 79.446373 | M5: =U61 -> 82.427419 | O5: =U92 -> 81.114706 | Q5: =U103 -> 0
A7: RESUMEN DE EFICIENCIAS | I7: 2do. | K7: =U132 -> 64.482074 | M7: =U150 -> 68.55547 | O7: =U181 -> 80.289743 | Q7: =U192 -> 0
I9: 3er | K9: =+U221 -> 85.390326 | M9: =+U239 -> 80.555441 | O9: =+U270 -> 76.824056 | Q9: =U281 -> 0
I11: 4to. | K11: =+U310 -> 0 | M11: =+U328 -> 0 | O11: =+U359 -> 0 | Q11: =U343 -> 0
H13: Promedio | K13: =(K11+K9+K7+K5)/3 -> 76.439591 | M13: =(M11+M9+M7+M5)/3 -> 77.179444 | O13: =(O11+O9+O7+O5)/3 -> 79.409501 | Q13: =(Q11+Q9+Q7+Q5)/3 -> 0
A18: PRIMER TURNO PRIMER TURNO PRIMER TURNO
A19: 1 TURNO | B19: HORARIO: | G19: 6:30-14:30 | K19: SUPERVISOR: | N19: DANIEL VALTIERRA | R19: DIA: | S19: DOMINGO | W19: FECHA: | Y19: 46131
A21: COMENTARIO DE PERSONAL
A25: F=FALTA, P=PERMISO, R=RETARDO, C=CASTIGO, I=INCAPACIDAD, V=VACACIONES, FL=FESTIVO LABORADO, FD=FESTIVO DESCANSADO, CL=CAMBIO DE LUGAR, B=BAJA, CT=CAMBIO DE TURNO
A27: Observaciones: | B27: 2.5 HRS T-201 CINTAS, 8 H T-202 ENDEREZADO / REPASO PEINE, 2.5 HRS T-209 FM PINZAS, 2.5 HRS T-301 FM MALLAS, 1.5 H T-303 FM TUBO ARRASTRE, 4 HRS T-314 4 HRS T-315 AJUSTE MAYOR DE CALIDAD
G30: Mínimo | H30: Máximo
A31: JACQUARD | B31: TEMPERATURA | G31: ='18 ABRIL (SABADO)'!G31 -> 20 | H31: ='18 ABRIL (SABADO)'!H31 -> 29 | Q31: =AVERAGE(K31,M31,O31) -> #DIV/0! | V31: =AVERAGE(S36:S41) -> 7.5
A32: SULZER | B32: HUMEDAD | G32: ='18 ABRIL (SABADO)'!G32 -> 60 | H32: ='18 ABRIL (SABADO)'!H32 -> 75 | Q32: =AVERAGE(K32,M32,O32) -> #DIV/0! | S32: MAQUINAS TRABAJANDO | V32: =COUNT(S36:S41) -> 5
K34: Marcador | M34: Marcador | O34: Marcas | S34: Horas | U34: Eficiencia | W34: Temp.
A35: Observaciones | B35: R | C35: P | D35: L | E35: tiempo | H35: vel | I35: telar | K35: Inicial | M35: Final | S35: 8
A36: ATADO RIZO | B36: 1 | H36: 280 | I36: 207 | K36: ='18 ABRIL (SABADO)'!M36 -> 553693 | M36: =K36+O36 -> 553747 | O36: 54 | S36: =+S35 -> 8 | U36: =O36/(H36*60*S36)*100000 -> 40.178571
H37: 300 | I37: 208 | K37: ='18 ABRIL (SABADO)'!M37 -> 617314 | M37: =K37+O37 -> 617432 | O37: 118 | S37: =+S36 -> 8 | U37: =O37/(H37*60*S37)*100000 -> 81.944444
A38: FM CINTAS | H38: 300 | I38: 209 | K38: ='18 ABRIL (SABADO)'!M38 -> 595076 | M38: =K38+O38 -> 595167 | O38: 91 | S38: 5.5 | U38: =O38/(H38*60*S38)*100000 -> 91.919192
H39: 290 | I39: 210 | K39: ='18 ABRIL (SABADO)'!M39 -> 681671.4 | M39: =K39+O39 -> 681806.4 | O39: 135 | S39: =+S35 -> 8 | U39: =O39/(H39*60*S39)*100000 -> 96.982759
H40: 290 | I40: 211 | K40: ='18 ABRIL (SABADO)'!M40 -> 738851.5 | M40: =K40+O40 -> 738971.5 | O40: 120 | S40: =+S39 -> 8 | U40: =O40/(H40*60*S40)*100000 -> 86.206897
U43: =AVERAGE(U36:U41) -> 79.446373 | W43: =AVERAGE(W36:W41) -> #DIV/0!
G45: Mínimo | H45: Máximo
A46: JACQUARD | B46: TEMPERATURA | G46: =$G$31 -> 20 | H46: =$H$31 -> 29 | Q46: =AVERAGE(K46,M46,O46) -> #DIV/0! | V46: =AVERAGE(S51:S59) -> 7.6875
A47: SMIT | B47: HUMEDAD | G47: =$G$32 -> 60 | H47: =$H$32 -> 75 | Q47: =AVERAGE(K47,M47,O47) -> #DIV/0! | S47: MAQUINAS TRABAJANDO | V47: =COUNT(S51:S59) -> 8
K49: Marcador | M49: Marcador | O49: Marcas | S49: Horas | U49: Eficiencia | W49: Temp.
A50: Observaciones | B50: R | C50: P | D50: L | E50: tiempo | H50: vel | I50: telar | K50: Inicial | M50: Final | S50: 8
A51: FM CINTAS | H51: 286 | I51: 201 | K51: ='18 ABRIL (SABADO)'!M51 -> 646878.6 | M51: =K51+O51 -> 646969.6 | O51: 91 | S51: 5.5 | U51: =O51/(H51*60*S51)*100000 -> 96.418733
A52: ENDEREZADO | H52: 271 | I52: 202 | K52: ='18 ABRIL (SABADO)'!M52 -> 753297.7 | M52: =K52+O52 -> 753297.7 | O52: 0
H53: 287 | I53: 203 | K53: ='18 ABRIL (SABADO)'!M53 -> 654308.8 | M53: =K53+O53 -> 654406.8 | O53: 98 | S53: =+S50 -> 8 | U53: =O53/(H53*60*S53)*100000 -> 71.138211
H54: 302 | I54: 204 | K54: ='18 ABRIL (SABADO)'!M54 -> 662404.7 | M54: =K54+O54 -> 662530.7 | O54: 126 | S54: =+S53 -> 8 | U54: =O54/(H54*60*S54)*100000 -> 86.92053
H55: 294 | I55: 205 | K55: ='18 ABRIL (SABADO)'!M55 -> 647459.7 | M55: =K55+O55 -> 647592.7 | O55: 133 | S55: =+S54 -> 8 | U55: =O55/(H55*60*S55)*100000 -> 94.246032
H56: 303 | I56: 206 | K56: ='18 ABRIL (SABADO)'!M56 -> 677317.3 | M56: =K56+O56 -> 677426.3 | O56: 109 | S56: =+S55 -> 8 | U56: =O56/(H56*60*S56)*100000 -> 74.944994
H57: 300 | I57: 213 | K57: ='18 ABRIL (SABADO)'!M57 -> 633074.9 | M57: =K57+O57 -> 633183.9 | O57: 109 | S57: =+S56 -> 8 | U57: =O57/(H57*60*S57)*100000 -> 75.694444
H58: 305 | I58: 214 | K58: ='18 ABRIL (SABADO)'!M58 -> 657160.9 | M58: =K58+O58 -> 657292.9 | O58: 132 | S58: =+S57 -> 8 | U58: =O58/(H58*60*S58)*100000 -> 90.163934
H59: 310 | I59: 215 | K59: ='18 ABRIL (SABADO)'!M59 -> 694514.2 | M59: =K59+O59 -> 694618.2 | O59: 104 | S59: =+S58 -> 8 | U59: =O59/(H59*60*S59)*100000 -> 69.892473
U61: =AVERAGE(U51:U59) -> 82.427419 | W61: =AVERAGE(W51:W58) -> #DIV/0!
G63: Mínimo | H63: Máximo
A64: SMIT LISO | B64: TEMPERATURA | G64: =$G$31 -> 20 | H64: =$H$31 -> 29 | Q64: =AVERAGE(K64,M64,O64) -> #DIV/0! | V64: =AVERAGE(S69:S90) -> 7.4545455
...

Sheet 18 ABRIL (SABADO)
A2: =TODAY()-1 -> 46133
I4: Turno | K4: Jaq | M4: Smit | O4: 300 | Q4: Karl M
I5: 1ro. | K5: =U43 -> 83.16092 | M5: =U61 -> 76.320769 | O5: =U92 -> 82.475943 | Q5: =U103 -> 0
A7: RESUMEN DE EFICIENCIAS | I7: 2do. | K7: =U132 -> 80.020183 | M7: =U150 -> 73.605767 | O7: =U181 -> 79.717194 | Q7: =U192 -> 0
I9: 3er | K9: =+U221 -> 78.663451 | M9: =+U239 -> 79.508751 | O9: =+U270 -> 80.828038 | Q9: =U281 -> 0
I11: 4to. | K11: =+U310 -> 0 | M11: =+U328 -> 0 | O11: =+U359 -> 0 | Q11: =U343 -> 0
H13: Promedio | K13: =(K11+K9+K7+K5)/3 -> 80.614851 | M13: =(M11+M9+M7+M5)/3 -> 76.478429 | O13: =(O11+O9+O7+O5)/3 -> 81.007058 | Q13: =(Q11+Q9+Q7+Q5)/3 -> 0
A18: PRIMER TURNO PRIMER TURNO PRIMER TURNO
A19: 1 TURNO | B19: HORARIO: | G19: 6:30-14:30 | K19: SUPERVISOR: | N19: DANIEL VALTIERRA | R19: DIA: | S19: SABADO | W19: FECHA: | Y19: 46130
A21: COMENTARIO DE PERSONAL
A25: F=FALTA, P=PERMISO, R=RETARDO, C=CASTIGO, I=INCAPACIDAD, V=VACACIONES, FL=FESTIVO LABORADO, FD=FESTIVO DESCANSADO, CL=CAMBIO DE LUGAR, B=BAJA, CT=CAMBIO DE TURNO
A27: Observaciones: | B27: 8 H T-202 REPASO TOTAL, 8 H T-301 MANTENIMIENTO A BALANCINES, 2.5 T-314, 2.5 T-320 AJUSTE CALIDAD
G30: Mínimo | H30: Máximo
A31: JACQUARD | B31: TEMPERATURA | G31: ='17 ABRIL (VIERNES)'!G31 -> 20 | H31: ='17 ABRIL (VIERNES)'!H31 -> 29 | Q31: =AVERAGE(K31,M31,O31) -> #DIV/0! | V31: =AVERAGE(S36:S41) -> 8
A32: SULZER | B32: HUMEDAD | G32: ='17 ABRIL (VIERNES)'!G32 -> 60 | H32: ='17 ABRIL (VIERNES)'!H32 -> 75 | Q32: =AVERAGE(K32,M32,O32) -> #DIV/0! | S32: MAQUINAS TRABAJANDO | V32: =COUNT(S36:S41) -> 5
K34: Marcador | M34: Marcador | O34: Marcas | S34: Horas | U34: Eficiencia | W34: Temp.
A35: Observaciones | B35: R | C35: P | D35: L | E35: tiempo | H35: vel | I35: telar | K35: Inicial | M35: Final | S35: 8
H36: 280 | I36: 207 | K36: ='17 ABRIL (VIERNES)'!M36 -> 553595 | M36: =K36+O36 -> 553693 | O36: 98 | S36: =+S35 -> 8 | U36: =O36/(H36*60*S36)*100000 -> 72.916667
H37: 300 | I37: 208 | K37: ='17 ABRIL (VIERNES)'!M37 -> 617198 | M37: =K37+O37 -> 617314 | O37: 116 | S37: =+S36 -> 8 | U37: =O37/(H37*60*S37)*100000 -> 80.555556
H38: 300 | I38: 209 | K38: ='17 ABRIL (VIERNES)'!M38 -> 594961 | M38: =K38+O38 -> 595076 | O38: 115 | S38: =+S37 -> 8 | U38: =O38/(H38*60*S38)*100000 -> 79.861111
H39: 290 | I39: 210 | K39: ='17 ABRIL (VIERNES)'!M39 -> 681539.4 | M39: =K39+O39 -> 681671.4 | O39: 132 | S39: =+S35 -> 8 | U39: =O39/(H39*60*S39)*100000 -> 94.827586
H40: 290 | I40: 211 | K40: ='17 ABRIL (VIERNES)'!M40 -> 738729.5 | M40: =K40+O40 -> 738851.5 | O40: 122 | S40: =+S39 -> 8 | U40: =O40/(H40*60*S40)*100000 -> 87.643678
U43: =AVERAGE(U36:U41) -> 83.16092 | W43: =AVERAGE(W36:W41) -> #DIV/0!
G45: Mínimo | H45: Máximo
A46: JACQUARD | B46: TEMPERATURA | G46: =$G$31 -> 20 | H46: =$H$31 -> 29 | Q46: =AVERAGE(K46,M46,O46) -> #DIV/0! | V46: =AVERAGE(S51:S59) -> 8
A47: SMIT | B47: HUMEDAD | G47: =$G$32 -> 60 | H47: =$H$32 -> 75 | Q47: =AVERAGE(K47,M47,O47) -> #DIV/0! | S47: MAQUINAS TRABAJANDO | V47: =COUNT(S51:S59) -> 8
K49: Marcador | M49: Marcador | O49: Marcas | S49: Horas | U49: Eficiencia | W49: Temp.
A50: Observaciones | B50: R | C50: P | D50: L | E50: tiempo | H50: vel | I50: telar | K50: Inicial | M50: Final | S50: 8
H51: 286 | I51: 201 | K51: ='17 ABRIL (VIERNES)'!M51 -> 646773.6 | M51: =K51+O51 -> 646878.6 | O51: 105 | S51: =+S50 -> 8 | U51: =O51/(H51*60*S51)*100000 -> 76.486014
A52: REPASO TOTAL | H52: 271 | I52: 202 | K52: ='17 ABRIL (VIERNES)'!M52 -> 753297.7 | M52: =K52+O52 -> 753297.7 | O52: 0
H53: 287 | I53: 203 | K53: ='17 ABRIL (VIERNES)'!M53 -> 654213.8 | M53: =K53+O53 -> 654308.8 | O53: 95 | S53: =+S50 -> 8 | U53: =O53/(H53*60*S53)*100000 -> 68.960511
H54: 302 | I54: 204 | K54: ='17 ABRIL (VIERNES)'!M54 -> 662299.7 | M54: =K54+O54 -> 662404.7 | O54: 105 | S54: =+S53 -> 8 | U54: =O54/(H54*60*S54)*100000 -> 72.433775
H55: 294 | I55: 205 | K55: ='17 ABRIL (VIERNES)'!M55 -> 647346.7 | M55: =K55+O55 -> 647459.7 | O55: 113 | S55: =+S54 -> 8 | U55: =O55/(H55*60*S55)*100000 -> 80.073696
H56: 303 | I56: 206 | K56: ='17 ABRIL (VIERNES)'!M56 -> 677229.3 | M56: =K56+O56 -> 677317.3 | O56: 88 | S56: =+S55 -> 8 | U56: =O56/(H56*60*S56)*100000 -> 60.506051
H57: 300 | I57: 213 | K57: ='17 ABRIL (VIERNES)'!M57 -> 632949.9 | M57: =K57+O57 -> 633074.9 | O57: 125 | S57: =+S56 -> 8 | U57: =O57/(H57*60*S57)*100000 -> 86.805556
